Workbook

Sheet 总览
C2: Wringy｜总览
C3: 情景草稿｜MYR｜新计量与反作弊开发未报价：零占位，非完整资金估计
C5: 核心结果 | D5: 保守 | E5: 基准 | F5: 扩张
C6: 公司累计回本（月序） | D6: =IF(MIN(保守现金流!D31:AM31)=999,"36个月内未回本",MIN(保守现金流!D31:AM31)) -> 36个月内未回本 | E6: =IF(MIN(基准现金流!D31:AM31)=999,"36个月内未回本",MIN(基准现金流!D31:AM31)) -> 25 | F6: =IF(MIN(扩张现金流!D31:AM31)=999,"36个月内未回本",MIN(扩张现金流!D31:AM31)) -> 18
C7: 首次单月经营不亏（月序） | D7: =IF(MIN(保守现金流!D32:AM32)=999,"36个月内未转正",MIN(保守现金流!D32:AM32)) -> 18 | E7: =IF(MIN(基准现金流!D32:AM32)=999,"36个月内未转正",MIN(基准现金流!D32:AM32)) -> 10 | F7: =IF(MIN(扩张现金流!D32:AM32)=999,"36个月内未转正",MIN(扩张现金流!D32:AM32)) -> 8
C8: 最大累计资金缺口／RM | D8: =MAX(0,-MIN(保守现金流!D29:AM29)) -> 383200 | E8: =MAX(0,-MIN(基准现金流!D29:AM29)) -> 326850 | F8: =MAX(0,-MIN(扩张现金流!D29:AM29)) -> 306950
C9: 36个月累计现金流／RM | D9: =保守现金流!AM29 -> -325725 | E9: =基准现金流!AM29 -> 596400 | F9: =扩张现金流!AM29 -> 2256675
C10: 36个月服务收入／RM | D10: =SUM(保守现金流!D14:AM14) -> 1104000 | E10: =SUM(基准现金流!D14:AM14) -> 3144000 | F10: =SUM(扩张现金流!D14:AM14) -> 6843000
C11: M36每月活动数 | D11: =保守现金流!AM6 -> 30 | E11: =基准现金流!AM6 -> 100 | F11: =扩张现金流!AM6 -> 240
C12: M36合格播放需求 | D12: =保守现金流!AM11 -> 60000000 | E12: =基准现金流!AM11 -> 200000000 | F12: =扩张现金流!AM11 -> 480000000
C13: 36个月新增品牌CAC／RM | D13: =SUM(保守现金流!D10:AM10) -> 45975 | E13: =SUM(基准现金流!D10:AM10) -> 143850 | F13: =SUM(扩张现金流!D10:AM10) -> 333075
C16: 20场／月：费率与利润不同 | D16: 数值
C17: 服务费率 | D17: =单位经济!D8 -> 0.15
C18: 平台收入／品牌支出 | D18: =单位经济!D9 -> 0.13043478
C19: 毛利率（含固定履约） | D19: =单位经济!D19 -> 0.53333333
C20: 贡献率（含每场佣金） | D20: =单位经济!D14 -> 0.5
C21: 经营结果（新增CAC前） | D21: =单位经济!D22 -> -2000
C22: 盈亏平衡场数（新增CAC前） | D22: =单位经济!D24 -> 23
C23: 品牌CAC简单回收（月） | D23: =品牌获客回收!D10 -> 1
C25: 公司回本包含开发、运营、启动及独立品牌CAC；融资现金不算回本收入。
C26: 单月经营结果是折旧摊销前规划指标；税后净利润未知。
C43: 月序 | D43: 保守累计现金 | E43: 基准累计现金 | F43: 扩张累计现金
C44: M1 | D44: =保守现金流!D29 -> -59437.5 | E44: =基准现金流!D29 -> -59437.5 | F44: =扩张现金流!D29 -> -59437.5
C45: M2 | D45: =保守现金流!E29 -> -118875 | E45: =基准现金流!E29 -> -118875 | F45: =扩张现金流!E29 -> -118875
C46: M3 | D46: =保守现金流!F29 -> -178312.5 | E46: =基准现金流!F29 -> -178312.5 | F46: =扩张现金流!F29 -> -178312.5
C47: M4 | D47: =保守现金流!G29 -> -237750 | E47: =基准现金流!G29 -> -237750 | F47: =扩张现金流!G29 -> -237750
C48: M5 | D48: =保守现金流!H29 -> -301750 | E48: =基准现金流!H29 -> -298750 | F48: =扩张现金流!H29 -> -295750
C49: M6 | D49: =保守现金流!I29 -> -315900 | E49: =基准现金流!I29 -> -310050 | F49: =扩张现金流!I29 -> -304200
C50: M7 | D50: =保守现金流!J29 -> -328625 | E50: =基准现金流!J29 -> -318500 | F50: =扩张现金流!J29 -> -306950
C51: M8 | D51: =保守现金流!K29 -> -339925 | E51: =基准现金流!K29 -> -324100 | F51: =扩张现金流!K29 -> -304000
C52: M9 | D52: =保守现金流!L29 -> -349800 | E52: =基准现金流!L29 -> -326850 | F52: =扩张现金流!L29 -> -295350
C53: M10 | D53: =保守现金流!M29 -> -358250 | E53: =基准现金流!M29 -> -326750 | F53: =扩张现金流!M29 -> -281000
C54: M11 | D54: =保守现金流!N29 -> -365275 | E54: =基准现金流!N29 -> -323800 | F54: =扩张现金流!N29 -> -260950
C55: M12 | D55: =保守现金流!O29 -> -370875 | E55: =基准现金流!O29 -> -318000 | F55: =扩张现金流!O29 -> -235200
C56: M13 | D56: =保守现金流!P29 -> -375050 | E56: =基准现金流!P29 -> -309350 | F56: =扩张现金流!P29 -> -203750
C57: M14 | D57: =保守现金流!Q29 -> -377800 | E57: =基准现金流!Q29 -> -297850 | F57: =扩张现金流!Q29 -> -166600
C58: M15 | D58: =保守现金流!R29 -> -380550 | E58: =基准现金流!R29 -> -283500 | F58: =扩张现金流!R29 -> -123750
C59: M16 | D59: =保守现金流!S29 -> -381875 | E59: =基准现金流!S29 -> -266300 | F59: =扩张现金流!S29 -> -75200
C60: M17 | D60: =保守现金流!T29 -> -383200 | E60: =基准现金流!T29 -> -246250 | F60: =扩张现金流!T29 -> -20950
C61: M18 | D61: =保守现金流!U29 -> -383100 | E61: =基准现金流!U29 -> -223350 | F61: =扩张现金流!U29 -> 40425
...

Sheet 假设
C2: Wringy｜假设
C5: 共同输入 | D5: 数值 | E5: 说明
C6: 每场已确认奖励 | D6: 10000 | E6: RM；旧商业算例，非客户订单
C7: 奖励外加服务费率 | D7: 0.15 | E7: 旧商业算例，非已批准定价
C8: 每千次合格播放奖励 | D8: 5 | E8: RM；旧商业算例
C9: 审核与支持／场 | D9: =D46*D47/60*D48 -> 300 | E9: 全量提交×含申诉平均分钟÷60×时薪；不得再重复加申诉成本
C10: 计量与数据／场 | D10: 100 | E10: RM；估计，非报价
C11: 支付／场 | D11: =IF(D49=0,D53,D6*(1+D7)*D50+D51) -> 150 | E11: 150为历史估计占位；模式1按全品牌资金计费，非仅服务费
C12: 异常损失／场 | D12: 50 | E12: RM；估计，非报价
C13: 活动获取／转介佣金／场 | D13: 150 | E13: RM；新增假设，每单发生；不属于品牌CAC
C14: 固定履约／月 | D14: 2000 | E14: RM；计入销售成本，也是固定17000的一部分
C15: 固定非履约运营／月 | D15: 15000 | E15: RM；不再另扣2000；原12000+5000重分类
C16: 历史开发预算锚点 | D16: 189750 | E16: RM；已含开发预备金，非新范围报价
C17: 新增计量与反作弊开发 | D17: 0 | E17: 未报价！零仅占位，资金需求是情景下限
C18: 建设期运营／月 | D18: 12000 | E18: RM；历史预算假设
C19: 一次性启动池 | D19: 50000 | E19: RM；M5首批品牌获客、试点及专业服务；不重复计CAC
C20: 独立销售品牌获客费 | D20: 1500 | E20: RM／新增品牌；M6起；不含每单佣金及固定销售工资
C21: 每活跃品牌每月活动 | D21: 2 | E21: 说明假设；当月新品牌也完成全部活动
C22: 月品牌流失率 | D22: 0.05 | E22: 说明假设；连续近似品牌数，不作人数承诺
C23: 期初可用公司现金 | D23: 0 | E23: RM；创始人投入未知；只影响余额，不影响回本
... C25: 建设月数 | D25: 4 | E25: M1–M4等额付开发费；非已签付款安排
C27: 蓝字浅黄＝可编辑输入；绿字＝跨表公式；月序为相对月份，无虚构开工日。
C28: 三情景并列计算，按要求各保留36个月明细；修改此处即自动更新相应情景。
D30: 1 | E30: 2 | F30: 3 | G30: 4 | H30: 5 | I30: 6 | J30: 7 | K30: 8 | L30: 9 | M30: 10 | N30: 11 | O30: 12 | P30: 13 | Q30: 14 | R30: 15 | S30: 16 | T30: 17 | U30: 18 | V30: 19 | W30: 20 | X30: 21 | Y30: 22 | Z30: 23 | AA30: 24 | AB30: 25 | AC30: 26 | AD30: 27 | AE30: 28 | AF30: 29 | AG30: 30 | AH30: 31 | AI30: 32 | AJ30: 33 | AK30: 34 | AL30: 35 | AM30: 36
C31: 保守｜活动数（说明输入） | D31: 0 | E31: 0 | F31: 0 | G31: 0 | H31: 4 | I31: 6 | J31: 8 | K31: 10 | L31: 12 | M31: 14 | N31: 16 | O31: 18 | P31: 20 | Q31: 20 | R31: 22 | S31: 22 | T31: 24 | U31: 24 | V31: 24 | W31: 26 | X31: 26 | Y31: 26 | Z31: 28 | AA31: 28 | AB31: 28 | AC31: 30 | AD31: 30 | AE31: 30 | AF31: 30 | AG31: 30 | AH31: 30 | AI31: 30 | AJ31: 30 | AK31: 30 | AL31: 30 | AM31: 30
C32: 基准｜活动数（说明输入） | D32: 0 | E32: 0 | F32: 0 | G32: 0 | H32: 8 | I32: 12 | J32: 16 | K32: 20 | L32: 24 | M32: 28 | N32: 32 | O32: 36 | P32: 40 | Q32: 44 | R32: 48 | S32: 52 | T32: 56 | U32: 60 | V32: 64 | W32: 68 | X32: 72 | Y32: 76 | Z32: 80 | AA32: 84 | AB32: 88 | AC32: 92 | AD32: 96 | AE32: 100 | AF32: 100 | AG32: 100 | AH32: 100 | AI32: 100 | AJ32: 100 | AK32: 100 | AL32: 100 | AM32: 100
C33: 扩张｜活动数（说明输入） | D33: 0 | E33: 0 | F33: 0 | G33: 0 | H33: 12 | I33: 20 | J33: 28 | K33: 36 | L33: 44 | M33: 52 | N33: 60 | O33: 68 | P33: 76 | Q33: 84 | R33: 92 | S33: 100 | T33: 110 | U33: 120 | V33: 130 | W33: 140 | X33: 150 | Y33: 160 | Z33: 170 | AA33: 180 | AB33: 190 | AC33: 200 | AD33: 210 | AE33: 220 | AF33: 230 | AG33: 240 | AH33: 240 | AI33: 240 | AJ33: 240 | AK33: 240 | AL33: 240 | AM33: 240
C36: 来源：phase-0/foundation/business-model-v2.md；belcort-handoff-v1.md（2026-09-10）
C37: 新增150佣金、600拆分、固定费用重分类及CAC路径：本轮授权情景假设，均非供应商报价。
C39: 会计口径：暂按代理规划假设，奖励代转款不计平台收入与成本；实际总额／净额待合同判断。
C40: https://www.ifrs.org/news-and-events/updates/ifric/2022/ifric-update-april-2022/
C41: https://openstax.org/books/principles-managerial-accounting/pages/3-1-explain-contribution-margin-and-calculate-contribution-margin-per-unit-contribution-margin-ratio-and-total-contribution-margin
C43: 不主张托管或支付许可已具备。费用均未报价；税、利息、收付款账期及折旧政策未建模。
C45: 审核、支付与收款驱动 | D45: 数值 | E45: 说明
C46: 全量审核提交／场 | D46: 200 | E46: 包括通过与拒绝的所有提交；不是仅已付款提交
C47: 平台平均审核分钟／提交 | D47: 1.5 | E47: 含异常及申诉的加权平均；假设，非效率基准；不含品牌自己审核
C48: 平台审核时薪 | D48: 60 | E48: RM／小时；假设，非报价
C49: 支付费模式 | D49: 0 | E49: 0＝原150占位；1＝全品牌资金×费率＋每场固定费
C50: 全品牌资金支付费率 | D50: 0.03 | E50: 3%仅敏感性假设，非Whop或市场报价
C51: 额外每场支付固定费 | D51: 0 | E51: RM；出款与固定费待报价，零仅占位
...

Sheet 单位经济
C2: Wringy｜单位经济
C5: 每场经济与20场示例 | D5: 数值
C6: 服务收入 | D6: =假设!$D$6*假设!$D$7 -> 1500
C7: 品牌总支出 | D7: =假设!$D$6+D6 -> 11500
C8: 服务费率 | D8: =假设!$D$7 -> 0.15
C9: 服务收入／品牌支出 | D9: =D6/D7 -> 0.13043478
C10: 所需合格播放／场 | D10: =假设!$D$6/假设!$D$8*1000 -> 2000000
C11: 可变履约成本／场 | D11: =SUM(假设!$D$9:$D$12) -> 600
C12: 活动获取佣金／场 | D12: =假设!$D$13 -> 150
C13: 贡献／场 | D13: =D6-D11-D12 -> 750
C14: 贡献率 | D14: =D13/D6 -> 0.5
C15: 月活动量 | D15: =假设!$D$24 -> 20
C16: 月收入 | D16: =D6*D15 -> 30000
C17: 月销售成本（含固定履约） | D17: =D11*D15+假设!$D$14 -> 14000
C18: 毛利 | D18: =D16-D17 -> 16000
C19: 毛利率 | D19: =D18/D16 -> 0.53333333
C20: 月贡献 | D20: =D13*D15 -> 15000
C21: 全部固定支出 | D21: =假设!$D$14+假设!$D$15 -> 17000
C22: 经营结果（新增品牌CAC前） | D22: =D20-D21 -> -2000
C23: 经营利润率（CAC前） | D23: =D22/D16 -> -0.066666667
C24: 盈亏平衡活动数（CAC前） | D24: =IF(D13<=0,"无法达成",ROUNDUP(D21/D13,0)) -> 23
C25: 税后净利润 | D25: 未知：税、利息、折旧政策未齐
C28: 毛利扣可变及固定履约；贡献扣全部每场可变成本；固定2000不重复扣除。
C29: 20场：经营亏损RM2,000，尚未扣新增品牌CAC；净利润未知。
C30: 15%服务费 ≠ 13.04%品牌支出占比 ≠ 53.33%毛利率（20场）。
C32: 毛利率以平台净服务费收入为分母；代理／主要责任人及实际收入确认仍待合同判断。

Sheet 保守现金流
C2: Wringy｜保守现金流
C3: 保守｜全部为说明情景；RM，M1–M36
D5: 1 | E5: 2 | F5: 3 | G5: 4 | H5: 5 | I5: 6 | J5: 7 | K5: 8 | L5: 9 | M5: 10 | N5: 11 | O5: 12 | P5: 13 | Q5: 14 | R5: 15 | S5: 16 | T5: 17 | U5: 18 | V5: 19 | W5: 20 | X5: 21 | Y5: 22 | Z5: 23 | AA5: 24 | AB5: 25 | AC5: 26 | AD5: 27 | AE5: 28 | AF5: 29 | AG5: 30 | AH5: 31 | AI5: 32 | AJ5: 33 | AK5: 34 | AL5: 35 | AM5: 36
C6: 活动数 | D6: =假设!D31 -> 0 | E6: =假设!E31 -> 0 | F6: =假设!F31 -> 0 | G6: =假设!G31 -> 0 | H6: =假设!H31 -> 4 | I6: =假设!I31 -> 6 | J6: =假设!J31 -> 8 | K6: =假设!K31 -> 10 | ... AM6: =假设!AM31 -> 30
C7: 活跃付费品牌（近似） | D7: =D6/假设!$D$21 -> 0 | E7: =E6/假设!$D$21 -> 0 | F7: =F6/假设!$D$21 -> 0 | G7: =G6/假设!$D$21 -> 0 | H7: =H6/假设!$D$21 -> 2 | I7: =I6/假设!$D$21 -> 3 | J7: =J6/假设!$D$21 -> 4 | K7: =K6/假设!$D$21 -> 5 | ... AM7: =AM6/假设!$D$21 -> 15
C8: 留存品牌 | D8: =0 -> 0 | E8: =MIN(E7,D7*(1-假设!$D$22)) -> 0 | F8: =MIN(F7,E7*(1-假设!$D$22)) -> 0 | G8: =MIN(G7,F7*(1-假设!$D$22)) -> 0 | H8: =MIN(H7,G7*(1-假设!$D$22)) -> 0 | I8: =MIN(I7,H7*(1-假设!$D$22)) -> 1.9 | J8: =MIN(J7,I7*(1-假设!$D$22)) -> 2.85 | K8: =MIN(K7,J7*(1-假设!$D$22)) -> 3.8 | L8: =MIN(L7,K7*(1-假设!$D$22)) -> 4.75 | ... AM8: =MIN(AM7,AL7*(1-假设!$D$22)) -> 14.25
C9: 新增／替补品牌 | D9: =MAX(0,D7-D8) -> 0 | E9: =MAX(0,E7-E8) -> 0 | F9: =MAX(0,F7-F8) -> 0 | G9: =MAX(0,G7-G8) -> 0 | H9: =MAX(0,H7-H8) -> 2 | I9: =MAX(0,I7-I8) -> 1.1 | J9: =MAX(0,J7-J8) -> 1.15 | K9: =MAX(0,K7-K8) -> 1.2 | ... AM9: =MAX(0,AM7-AM8) -> 0.75
C10: 独立品牌CAC现金支出 | D10: =IF(D$5<=假设!$D$25+1,0,D9*假设!$D$20) -> 0 | E10: =IF(E$5<=假设!$D$25+1,0,E9*假设!$D$20) -> 0 | F10: =IF(F$5<=假设!$D$25+1,0,F9*假设!$D$20) -> 0 | G10: =IF(G$5<=假设!$D$25+1,0,G9*假设!$D$20) -> 0 | H10: =IF(H$5<=假设!$D$25+1,0,H9*假设!$D$20) -> 0 | I10: =IF(I$5<=假设!$D$25+1,0,I9*假设!$D$20) -> 1650 | J10: =IF(J$5<=假设!$D$25+1,0,J9*假设!$D$20) -> 1725 | K10: =IF(K$5<=假设!$D$25+1,0,K9*假设!$D$20) -> 1800 | ... AM10: =IF(AM$5<=假设!$D$25+1,0,AM9*假设!$D$20) -> 1125
C11: 合格播放需求 | D11: =D6*单位经济!$D$10 -> 0 | E11: =E6*单位经济!$D$10 -> 0 | F11: =F6*单位经济!$D$10 -> 0 | G11: =G6*单位经济!$D$10 -> 0 | H11: =H6*单位经济!$D$10 -> 8000000 | I11: =I6*单位经济!$D$10 -> 12000000 | J11: =J6*单位经济!$D$10 -> 16000000 | K11: =K6*单位经济!$D$10 -> 20000000 | ... AM11: =AM6*单位经济!$D$10 -> 60000000
C12: 创作者奖励代转（非收入） | D12: =D6*假设!$D$6 -> 0 | E12: =E6*假设!$D$6 -> 0 | F12: =F6*假设!$D$6 -> 0 | G12: =G6*假设!$D$6 -> 0 | H12: =H6*假设!$D$6 -> 40000 | I12: =I6*假设!$D$6 -> 60000 | J12: =J6*假设!$D$6 -> 80000 | K12: =K6*假设!$D$6 -> 100000 | ... AM12: =AM6*假设!$D$6 -> 300000
C13: 品牌总支出（未税） | D13: =D12+D14 -> 0 | E13: =E12+E14 -> 0 | F13: =F12+F14 -> 0 | G13: =G12+G14 -> 0 | H13: =H12+H14 -> 46000 | I13: =I12+I14 -> 69000 | J13: =J12+J14 -> 92000 | K13: =K12+K14 -> 115000 | ... AM13: =AM12+AM14 -> 345000
C14: 平台服务收入 | D14: =D6*单位经济!$D$6 -> 0 | E14: =E6*单位经济!$D$6 -> 0 | F14: =F6*单位经济!$D$6 -> 0 | G14: =G6*单位经济!$D$6 -> 0 | H14: =H6*单位经济!$D$6 -> 6000 | I14: =I6*单位经济!$D$6 -> 9000 | J14: =J6*单位经济!$D$6 -> 12000 | K14: =K6*单位经济!$D$6 -> 15000 | ... AM14: =AM6*单位经济!$D$6 -> 45000
C15: 可变履约成本 | D15: =D6*单位经济!$D$11 -> 0 | E15: =E6*单位经济!$D$11 -> 0 | F15: =F6*单位经济!$D$11 -> 0 | G15: =G6*单位经济!$D$11 -> 0 | H15: =H6*单位经济!$D$11 -> 2400 | I15: =I6*单位经济!$D$11 -> 3600 | J15: =J6*单位经济!$D$11 -> 4800 | K15: =K6*单位经济!$D$11 -> 6000 | ... AM15: =AM6*单位经济!$D$11 -> 18000
C16: 固定履约成本 | D16: =IF(D$5>假设!$D$25,假设!$D$14,0) -> 0 | E16: =IF(E$5>假设!$D$25,假设!$D$14,0) -> 0 | F16: =IF(F$5>假设!$D$25,假设!$D$14,0) -> 0 | G16: =IF(G$5>假设!$D$25,假设!$D$14,0) -> 0 | H16: =IF(H$5>假设!$D$25,假设!$D$14,0) -> 2000 | I16: =IF(I$5>假设!$D$25,假设!$D$14,0) -> 2000 | J16: =IF(J$5>假设!$D$25,假设!$D$14,0) -> 2000 | K16: =IF(K$5>假设!$D$25,假设!$D$14,0) -> 2000 | ... AM16: =IF(AM$5>假设!$D$25,假设!$D$14,0) -> 2000
C17: 销售成本合计 | D17: =SUM(D15:D16) -> 0 | E17: =SUM(E15:E16) -> 0 | F17: =SUM(F15:F16) -> 0 | G17: =SUM(G15:G16) -> 0 | H17: =SUM(H15:H16) -> 4400 | I17: =SUM(I15:I16) -> 5600 | J17: =SUM(J15:J16) -> 6800 | K17: =SUM(K15:K16) -> 8000 | ... AM17: =SUM(AM15:AM16) -> 20000
C18: 毛利 | D18: =D14-D17 -> 0 | E18: =E14-E17 -> 0 | F18: =F14-F17 -> 0 | G18: =G14-G17 -> 0 | H18: =H14-H17 -> 1600 | I18: =I14-I17 -> 3400 | J18: =J14-J17 -> 5200 | K18: =K14-K17 -> 7000 | ... AM18: =AM14-AM17 -> 25000
C19: 毛利率 | D19: =IF(D14=0,"不适用",D18/D14) -> 不适用 | E19: =IF(E14=0,"不适用",E18/E14) -> 不适用 | F19: =IF(F14=0,"不适用",F18/F14) -> 不适用 | G19: =IF(G14=0,"不适用",G18/G14) -> 不适用 | H19: =IF(H14=0,"不适用",H18/H14) -> 0.26666667 | I19: =IF(I14=0,"不适用",I18/I14) -> 0.37777778 | J19: =IF(J14=0,"不适用",J18/J14) -> 0.43333333 | K19: =IF(K14=0,"不适用",K18/K14) -> 0.46666667 | ... AM19: =IF(AM14=0,"不适用",AM18/AM14) -> 0.55555556
C20: 活动获取佣金 | D20: =D6*假设!$D$13 -> 0 | E20: =E6*假设!$D$13 -> 0 | F20: =F6*假设!$D$13 -> 0 | G20: =G6*假设!$D$13 -> 0 | H20: =H6*假设!$D$13 -> 600 | I20: =I6*假设!$D$13 -> 900 | J20: =J6*假设!$D$13 -> 1200 | K20: =K6*假设!$D$13 -> 1500 | ... AM20: =AM6*假设!$D$13 -> 4500
C21: 贡献（CAC前） | D21: =D14-D15-D20 -> 0 | E21: =E14-E15-E20 -> 0 | F21: =F14-F15-F20 -> 0 | G21: =G14-G15-G20 -> 0 | H21: =H14-H15-H20 -> 3000 | I21: =I14-I15-I20 -> 4500 | J21: =J14-J15-J20 -> 6000 | K21: =K14-K15-K20 -> 7500 | ... AM21: =AM14-AM15-AM20 -> 22500
C22: 固定非履约支出 | D22: =IF(D$5>假设!$D$25,假设!$D$15,0) -> 0 | E22: =IF(E$5>假设!$D$25,假设!$D$15,0) -> 0 | F22: =IF(F$5>假设!$D$25,假设!$D$15,0) -> 0 | G22: =IF(G$5>假设!$D$25,假设!$D$15,0) -> 0 | H22: =IF(H$5>假设!$D$25,假设!$D$15,0) -> 15000 | I22: =IF(I$5>假设!$D$25,假设!$D$15,0) -> 15000 | J22: =IF(J$5>假设!$D$25,假设!$D$15,0) -> 15000 | K22: =IF(K$5>假设!$D$25,假设!$D$15,0) -> 15000 | ... AM22: =IF(AM$5>假设!$D$25,假设!$D$15,0) -> 15000
C23: 建设期运营支出 | D23: =IF(D$5<=假设!$D$25,假设!$D$18,0) -> 12000 | E23: =IF(E$5<=假设!$D$25,假设!$D$18,0) -> 12000 | F23: =IF(F$5<=假设!$D$25,假设!$D$18,0) -> 12000 | G23: =IF(G$5<=假设!$D$25,假设!$D$18,0) -> 12000 | H23: =IF(H$5<=假设!$D$25,假设!$D$18,0) -> 0 | I23: =IF(I$5<=假设!$D$25,假设!$D$18,0) -> 0 | J23: =IF(J$5<=假设!$D$25,假设!$D$18,0) -> 0 | K23: =IF(K$5<=假设!$D$25,假设!$D$18,0) -> 0 | ... AM23: =IF(AM$5<=假设!$D$25,假设!$D$18,0) -> 0
C24: 经营结果（含品牌CAC） | D24: =D18-D20-D22-D23-D10 -> -12000 | E24: =E18-E20-E22-E23-E10 -> -12000 | F24: =F18-F20-F22-F23-F10 -> -12000 | G24: =G18-G20-G22-G23-G10 -> -12000 | H24: =H18-H20-H22-H23-H10 -> -14000 | I24: =I18-I20-I22-I23-I10 -> -14150 | J24: =J18-J20-J22-J23-J10 -> -12725 | K24: =K18-K20-K22-K23-K10 -> -11300 | ... AM24: =AM18-AM20-AM22-AM23-AM10 -> 4375
C25: 经营利润率 | D25: =IF(D14=0,"不适用",D24/D14) -> 不适用 | E25: =IF(E14=0,"不适用",E24/E14) -> 不适用 | F25: =IF(F14=0,"不适用",F24/F14) -> 不适用 | G25: =IF(G14=0,"不适用",G24/G14) -> 不适用 | H25: =IF(H14=0,"不适用",H24/H14) -> -2.3333333 | I25: =IF(I14=0,"不适用",I24/I14) -> -1.5722222 | J25: =IF(J14=0,"不适用",J24/J14) -> -1.0604167 | K25: =IF(K14=0,"不适用",K24/K14) -> -0.75333333 | ... AM25: =IF(AM14=0,"不适用",AM24/AM14) -> 0.097222222
C26: 开发现金支付 | D26: =IF(D$5<=假设!$D$25,(假设!$D$16+假设!$D$17)/假设!$D$25,0) -> 47437.5 | E26: =IF(E$5<=假设!$D$25,(假设!$D$16+假设!$D$17)/假设!$D$25,0) -> 47437.5 | F26: =IF(F$5<=假设!$D$25,(假设!$D$16+假设!$D$17)/假设!$D$25,0) -> 47437.5 | G26: =IF(G$5<=假设!$D$25,(假设!$D$16+假设!$D$17)/假设!$D$25,0) -> 47437.5 | H26: =IF(H$5<=假设!$D$25,(假设!$D$16+假设!$D$17)/假设!$D$25,0) -> 0 | I26: =IF(I$5<=假设!$D$25,(假设!$D$16+假设!$D$17)/假设!$D$25,0) -> 0 | J26: =IF(J$5<=假设!$D$25,(假设!$D$16+假设!$D$17)/假设!$D$25,0) -> 0 | K26: =IF(K$5<=假设!$D$25,(假设!$D$16+假设!$D$17)/假设!$D$25,0) -> 0 | ... AM26: =IF(AM$5<=假设!$D$25,(假设!$D$16+假设!$D$17)/假设!$D$25,0) -> 0
C27: 一次性启动现金支出 | D27: =IF(D$5=假设!$D$25+1,假设!$D$19,0) -> 0 | E27: =IF(E$5=假设!$D$25+1,假设!$D$19,0) -> 0 | F27: =IF(F$5=假设!$D$25+1,假设!$D$19,0) -> 0 | G27: =IF(G$5=假设!$D$25+1,假设!$D$19,0) -> 0 | H27: =IF(H$5=假设!$D$25+1,假设!$D$19,0) -> 50000 | I27: =IF(I$5=假设!$D$25+1,假设!$D$19,0) -> 0 | J27: =IF(J$5=假设!$D$25+1,假设!$D$19,0) -> 0 | K27: =IF(K$5=假设!$D$25+1,假设!$D$19,0) -> 0 | ... AM27: =IF(AM$5=假设!$D$25+1,假设!$D$19,0) -> 0
C28: 融资前税前现金流 | D28: =D24-D26-D27-D14+D33 -> -59437.5 | E28: =E24-E26-E27-E14+E33 -> -59437.5 | F28: =F24-F26-F27-F14+F33 -> -59437.5 | G28: =G24-G26-G27-G14+G33 -> -59437.5 | H28: =H24-H26-H27-H14+H33 -> -64000 | I28: =I24-I26-I27-I14+I33 -> -14150 | J28: =J24-J26-J27-J14+J33 -> -12725 | K28: =K24-K26-K27-K14+K33 -> -11300 | ... AM28: =AM24-AM26-AM27-AM14+AM33 -> 4375
C29: 累计公司现金流 | D29: =D28 -> -59437.5 | E29: =D29+E28 -> -118875 | F29: =E29+F28 -> -178312.5 | G29: =F29+G28 -> -237750 | H29: =G29+H28 -> -301750 | I29: =H29+I28 -> -315900 | J29: =I29+J28 -> -328625 | K29: =J29+K28 -> -339925 | L29: =K29+L28 -> -349800 | ... AM29: =AL29+AM28 -> -325725
C30: 含期初现金的余额 | D30: =假设!$D$23+D29 -> -59437.5 | E30: =假设!$D$23+E29 -> -118875 | F30: =假设!$D$23+F29 -> -178312.5 | G30: =假设!$D$23+G29 -> -237750 | H30: =假设!$D$23+H29 -> -301750 | I30: =假设!$D$23+I29 -> -315900 | J30: =假设!$D$23+J29 -> -328625 | K30: =假设!$D$23+K29 -> -339925 | ... AM30: =假设!$D$23+AM29 -> -325725
C31: 累计回本月标记 | D31: =IF(AND(D$5>假设!$D$25,D29>=0),D$5,999) -> 999 | E31: =IF(AND(E$5>假设!$D$25,E29>=0),E$5,999) -> 999 | F31: =IF(AND(F$5>假设!$D$25,F29>=0),F$5,999) -> 999 | G31: =IF(AND(G$5>假设!$D$25,G29>=0),G$5,999) -> 999 | H31: =IF(AND(H$5>假设!$D$25,H29>=0),H$5,999) -> 999 | I31: =IF(AND(I$5>假设!$D$25,I29>=0),I$5,999) -> 999 | J31: =IF(AND(J$5>假设!$D$25,J29>=0),J$5,999) -> 999 | K31: =IF(AND(K$5>假设!$D$25,K29>=0),K$5,999) -> 999 | ... AM31: =IF(AND(AM$5>假设!$D$25,AM29>=0),AM$5,999) -> 999
C32: 单月经营不亏标记 | D32: =IF(AND(D$5>假设!$D$25,D24>=0),D$5,999) -> 999 | E32: =IF(AND(E$5>假设!$D$25,E24>=0),E$5,999) -> 999 | F32: =IF(AND(F$5>假设!$D$25,F24>=0),F$5,999) -> 999 | G32: =IF(AND(G$5>假设!$D$25,G24>=0),G$5,999) -> 999 | H32: =IF(AND(H$5>假设!$D$25,H24>=0),H$5,999) -> 999 | I32: =IF(AND(I$5>假设!$D$25,I24>=0),I$5,999) -> 999 | J32: =IF(AND(J$5>假设!$D$25,J24>=0),J$5,999) -> 999 | K32: =IF(AND(K$5>假设!$D$25,K24>=0),K$5,999) -> 999 | ... AM32: =IF(AND(AM$5>假设!$D$25,AM24>=0),AM$5,999) -> 36
C33: 当月服务费现金收款 | D33: =IF(假设!$D$52=0,D14,0) -> 0 | E33: =IF(假设!$D$52=0,E14,D14) -> 0 | F33: =IF(假设!$D$52=0,F14,E14) -> 0 | G33: =IF(假设!$D$52=0,G14,F14) -> 0 | H33: =IF(假设!$D$52=0,H14,G14) -> 6000 | I33: =IF(假设!$D$52=0,I14,H14) -> 9000 | J33: =IF(假设!$D$52=0,J14,I14) -> 12000 | K33: =IF(假设!$D$52=0,K14,J14) -> 15000 | L33: =IF(假设!$D$52=0,L14,K14) -> 18000 | ... AM33: =IF(假设!$D$52=0,AM14,AL14) -> 45000
C34: 期末服务费应收款 | D34: =D14-D33 -> 0 | E34: =D34+E14-E33 -> 0 | F34: =E34+F14-F33 -> 0 | G34: =F34+G14-G33 -> 0 | H34: =G34+H14-H33 -> 0 | I34: =H34+I14-I33 -> 0 | J34: =I34+J14-J33 -> 0 | K34: =J34+K14-K33 -> 0 | L34: =K34+L14-L33 -> 0 | ... AM34: =AL34+AM14-AM33 -> 0
C35: M5首批获客已计入启动池；M6起新增/替补品牌另付CAC。当月获得品牌当月即完成全部活动。
C36: 现金流已含0/1月服务费收款延迟；未计税、利息及其余营运资金；不作税后净利。
C37: 固定费用不随规模增长仅为情景假设；扩张需另验容量、招聘、数据吞吐及报价。
C39: 支付费敏感性：全品牌资金费率 | D39: =假设!$D$50 -> 0.03 | E39: =假设!$D$50 -> 0.03 | F39: =假设!$D$50 -> 0.03 | G39: =假设!$D$50 -> 0.03 | H39: =假设!$D$50 -> 0.03 | I39: =假设!$D$50 -> 0.03 | J39: =假设!$D$50 -> 0.03 | K39: =假设!$D$50 -> 0.03 | ... AM39: =假设!$D$50 -> 0.03
C40: 敏感性现金流（同收款账期） | D40: =D28-(单位经济!$D$7*D39+假设!$D$51-假设!$D$11)*D6 -> -59437.5 | E40: =E28-(单位经济!$D$7*E39+假设!$D$51-假设!$D$11)*E6 -> -59437.5 | F40: =F28-(单位经济!$D$7*F39+假设!$D$51-假设!$D$11)*F6 -> -59437.5 | G40: =G28-(单位经济!$D$7*G39+假设!$D$51-假设!$D$11)*G6 -> -59437.5 | H40: =H28-(单位经济!$D$7*H39+假设!$D$51-假设!$D$11)*H6 -> -64780 | I40: =I28-(单位经济!$D$7*I39+假设!$D$51-假设!$D$11)*I6 -> -15320 | J40: =J28-(单位经济!$D$7*J39+假设!$D$51-假设!$D$11)*J6 -> -14285 | K40: =K28-(单位经济!$D$7*K39+假设!$D$51-假设!$D$11)*K6 -> -13250 | ... AM40: =AM28-(单位经济!$D$7*AM39+假设!$D$51-假设!$D$11)*AM6 -> -1475
C41: 敏感性累计现金流 | D41: =D40 -> -59437.5 | E41: =D41+E40 -> -118875 | F41: =E41+F40 -> -178312.5 | G41: =F41+G40 -> -237750 | H41: =G41+H40 -> -302530 | I41: =H41+I40 -> -317850 | J41: =I41+J40 -> -332135 | K41: =J41+K40 -> -345385 | L41: =K41+L40 -> -357600 | ... AM41: =AL41+AM40 -> -469245
C42: 敏感性回本月标记 | D42: =IF(AND(D$5>假设!$D$25,D41>=0),D$5,999) -> 999 | E42: =IF(AND(E$5>假设!$D$25,E41>=0),E$5,999) -> 999 | F42: =IF(AND(F$5>假设!$D$25,F41>=0),F$5,999) -> 999 | G42: =IF(AND(G$5>假设!$D$25,G41>=0),G$5,999) -> 999 | H42: =IF(AND(H$5>假设!$D$25,H41>=0),H$5,999) -> 999 | I42: =IF(AND(I$5>假设!$D$25,I41>=0),I$5,999) -> 999 | J42: =IF(AND(J$5>假设!$D$25,J41>=0),J$5,999) -> 999 | K42: =IF(AND(K$5>假设!$D$25,K41>=0),K$5,999) -> 999 | ... AM42: =IF(AND(AM$5>假设!$D$25,AM41>=0),AM$5,999) -> 999

Sheet 基准现金流
C2: Wringy｜基准现金流
C3: 基准｜全部为说明情景；RM，M1–M36
D5: 1 | E5: 2 | F5: 3 | G5: 4 | H5: 5 | I5: 6 | J5: 7 | K5: 8 | L5: 9 | M5: 10 | N5: 11 | O5: 12 | P5: 13 | Q5: 14 | R5: 15 | S5: 16 | T5: 17 | U5: 18 | V5: 19 | W5: 20 | X5: 21 | Y5: 22 | Z5: 23 | AA5: 24 | AB5: 25 | AC5: 26 | AD5: 27 | AE5: 28 | AF5: 29 | AG5: 30 | AH5: 31 | AI5: 32 | AJ5: 33 | AK5: 34 | AL5: 35 | AM5: 36
C6: 活动数 | D6: =假设!D32 -> 0 | E6: =假设!E32 -> 0 | F6: =假设!F32 -> 0 | G6: =假设!G32 -> 0 | H6: =假设!H32 -> 8 | I6: =假设!I32 -> 12 | J6: =假设!J32 -> 16 | K6: =假设!K32 -> 20 | ... AM6: =假设!AM32 -> 100
C7: 活跃付费品牌（近似） | D7: =D6/假设!$D$21 -> 0 | E7: =E6/假设!$D$21 -> 0 | F7: =F6/假设!$D$21 -> 0 | G7: =G6/假设!$D$21 -> 0 | H7: =H6/假设!$D$21 -> 4 | I7: =I6/假设!$D$21 -> 6 | J7: =J6/假设!$D$21 -> 8 | K7: =K6/假设!$D$21 -> 10 | ... AM7: =AM6/假设!$D$21 -> 50
C8: 留存品牌 | D8: =0 -> 0 | E8: =MIN(E7,D7*(1-假设!$D$22)) -> 0 | F8: =MIN(F7,E7*(1-假设!$D$22)) -> 0 | G8: =MIN(G7,F7*(1-假设!$D$22)) -> 0 | H8: =MIN(H7,G7*(1-假设!$D$22)) -> 0 | I8: =MIN(I7,H7*(1-假设!$D$22)) -> 3.8 | J8: =MIN(J7,I7*(1-假设!$D$22)) -> 5.7 | K8: =MIN(K7,J7*(1-假设!$D$22)) -> 7.6 | L8: =MIN(L7,K7*(1-假设!$D$22)) -> 9.5 | ... AM8: =MIN(AM7,AL7*(1-假设!$D$22)) -> 47.5
C9: 新增／替补品牌 | D9: =MAX(0,D7-D8) -> 0 | E9: =MAX(0,E7-E8) -> 0 | F9: =MAX(0,F7-F8) -> 0 | G9: =MAX(0,G7-G8) -> 0 | H9: =MAX(0,H7-H8) -> 4 | I9: =MAX(0,I7-I8) -> 2.2 | J9: =MAX(0,J7-J8) -> 2.3 | K9: =MAX(0,K7-K8) -> 2.4 | ... AM9: =MAX(0,AM7-AM8) -> 2.5
C10: 独立品牌CAC现金支出 | D10: =IF(D$5<=假设!$D$25+1,0,D9*假设!$D$20) -> 0 | E10: =IF(E$5<=假设!$D$25+1,0,E9*假设!$D$20) -> 0 | F10: =IF(F$5<=假设!$D$25+1,0,F9*假设!$D$20) -> 0 | G10: =IF(G$5<=假设!$D$25+1,0,G9*假设!$D$20) -> 0 | H10: =IF(H$5<=假设!$D$25+1,0,H9*假设!$D$20) -> 0 | I10: =IF(I$5<=假设!$D$25+1,0,I9*假设!$D$20) -> 3300 | J10: =IF(J$5<=假设!$D$25+1,0,J9*假设!$D$20) -> 3450 | K10: =IF(K$5<=假设!$D$25+1,0,K9*假设!$D$20) -> 3600 | ... AM10: =IF(AM$5<=假设!$D$25+1,0,AM9*假设!$D$20) -> 3750
C11: 合格播放需求 | D11: =D6*单位经济!$D$10 -> 0 | E11: =E6*单位经济!$D$10 -> 0 | F11: =F6*单位经济!$D$10 -> 0 | G11: =G6*单位经济!$D$10 -> 0 | H11: =H6*单位经济!$D$10 -> 16000000 | I11: =I6*单位经济!$D$10 -> 24000000 | J11: =J6*单位经济!$D$10 -> 32000000 | K11: =K6*单位经济!$D$10 -> 40000000 | ... AM11: =AM6*单位经济!$D$10 -> 200000000
C12: 创作者奖励代转（非收入） | D12: =D6*假设!$D$6 -> 0 | E12: =E6*假设!$D$6 -> 0 | F12: =F6*假设!$D$6 -> 0 | G12: =G6*假设!$D$6 -> 0 | H12: =H6*假设!$D$6 -> 80000 | I12: =I6*假设!$D$6 -> 120000 | J12: =J6*假设!$D$6 -> 160000 | K12: =K6*假设!$D$6 -> 200000 | ... AM12: =AM6*假设!$D$6 -> 1000000
C13: 品牌总支出（未税） | D13: =D12+D14 -> 0 | E13: =E12+E14 -> 0 | F13: =F12+F14 -> 0 | G13: =G12+G14 -> 0 | H13: =H12+H14 -> 92000 | I13: =I12+I14 -> 138000 | J13: =J12+J14 -> 184000 | K13: =K12+K14 -> 230000 | ... AM13: =AM12+AM14 -> 1150000
C14: 平台服务收入 | D14: =D6*单位经济!$D$6 -> 0 | E14: =E6*单位经济!$D$6 -> 0 | F14: =F6*单位经济!$D$6 -> 0 | G14: =G6*单位经济!$D$6 -> 0 | H14: =H6*单位经济!$D$6 -> 12000 | I14: =I6*单位经济!$D$6 -> 18000 | J14: =J6*单位经济!$D$6 -> 24000 | K14: =K6*单位经济!$D$6 -> 30000 | ... AM14: =AM6*单位经济!$D$6 -> 150000
C15: 可变履约成本 | D15: =D6*单位经济!$D$11 -> 0 | E15: =E6*单位经济!$D$11 -> 0 | F15: =F6*单位经济!$D$11 -> 0 | G15: =G6*单位经济!$D$11 -> 0 | H15: =H6*单位经济!$D$11 -> 4800 | I15: =I6*单位经济!$D$11 -> 7200 | J15: =J6*单位经济!$D$11 -> 9600 | K15: =K6*单位经济!$D$11 -> 12000 | ... AM15: =AM6*单位经济!$D$11 -> 60000
C16: 固定履约成本 | D16: =IF(D$5>假设!$D$25,假设!$D$14,0) -> 0 | E16: =IF(E$5>假设!$D$25,假设!$D$14,0) -> 0 | F16: =IF(F$5>假设!$D$25,假设!$D$14,0) -> 0 | G16: =IF(G$5>假设!$D$25,假设!$D$14,0) -> 0 | H16: =IF(H$5>假设!$D$25,假设!$D$14,0) -> 2000 | I16: =IF(I$5>假设!$D$25,假设!$D$14,0) -> 2000 | J16: =IF(J$5>假设!$D$25,假设!$D$14,0) -> 2000 | K16: =IF(K$5>假设!$D$25,假设!$D$14,0) -> 2000 | ... AM16: =IF(AM$5>假设!$D$25,假设!$D$14,0) -> 2000
C17: 销售成本合计 | D17: =SUM(D15:D16) -> 0 | E17: =SUM(E15:E16) -> 0 | F17: =SUM(F15:F16) -> 0 | G17: =SUM(G15:G16) -> 0 | H17: =SUM(H15:H16) -> 6800 | I17: =SUM(I15:I16) -> 9200 | J17: =SUM(J15:J16) -> 11600 | K17: =SUM(K15:K16) -> 14000 | ... AM17: =SUM(AM15:AM16) -> 62000
C18: 毛利 | D18: =D14-D17 -> 0 | E18: =E14-E17 -> 0 | F18: =F14-F17 -> 0 | G18: =G14-G17 -> 0 | H18: =H14-H17 -> 5200 | I18: =I14-I17 -> 8800 | J18: =J14-J17 -> 12400 | K18: =K14-K17 -> 16000 | ... AM18: =AM14-AM17 -> 88000
C19: 毛利率 | D19: =IF(D14=0,"不适用",D18/D14) -> 不适用 | E19: =IF(E14=0,"不适用",E18/E14) -> 不适用 | F19: =IF(F14=0,"不适用",F18/F14) -> 不适用 | G19: =IF(G14=0,"不适用",G18/G14) -> 不适用 | H19: =IF(H14=0,"不适用",H18/H14) -> 0.43333333 | I19: =IF(I14=0,"不适用",I18/I14) -> 0.48888889 | J19: =IF(J14=0,"不适用",J18/J14) -> 0.51666667 | K19: =IF(K14=0,"不适用",K18/K14) -> 0.53333333 | ... AM19: =IF(AM14=0,"不适用",AM18/AM14) -> 0.58666667
C20: 活动获取佣金 | D20: =D6*假设!$D$13 -> 0 | E20: =E6*假设!$D$13 -> 0 | F20: =F6*假设!$D$13 -> 0 | G20: =G6*假设!$D$13 -> 0 | H20: =H6*假设!$D$13 -> 1200 | I20: =I6*假设!$D$13 -> 1800 | J20: =J6*假设!$D$13 -> 2400 | K20: =K6*假设!$D$13 -> 3000 | ... AM20: =AM6*假设!$D$13 -> 15000
C21: 贡献（CAC前） | D21: =D14-D15-D20 -> 0 | E21: =E14-E15-E20 -> 0 | F21: =F14-F15-F20 -> 0 | G21: =G14-G15-G20 -> 0 | H21: =H14-H15-H20 -> 6000 | I21: =I14-I15-I20 -> 9000 | J21: =J14-J15-J20 -> 12000 | K21: =K14-K15-K20 -> 15000 | ... AM21: =AM14-AM15-AM20 -> 75000
C22: 固定非履约支出 | D22: =IF(D$5>假设!$D$25,假设!$D$15,0) -> 0 | E22: =IF(E$5>假设!$D$25,假设!$D$15,0) -> 0 | F22: =IF(F$5>假设!$D$25,假设!$D$15,0) -> 0 | G22: =IF(G$5>假设!$D$25,假设!$D$15,0) -> 0 | H22: =IF(H$5>假设!$D$25,假设!$D$15,0) -> 15000 | I22: =IF(I$5>假设!$D$25,假设!$D$15,0) -> 15000 | J22: =IF(J$5>假设!$D$25,假设!$D$15,0) -> 15000 | K22: =IF(K$5>假设!$D$25,假设!$D$15,0) -> 15000 | ... AM22: =IF(AM$5>假设!$D$25,假设!$D$15,0) -> 15000
C23: 建设期运营支出 | D23: =IF(D$5<=假设!$D$25,假设!$D$18,0) -> 12000 | E23: =IF(E$5<=假设!$D$25,假设!$D$18,0) -> 12000 | F23: =IF(F$5<=假设!$D$25,假设!$D$18,0) -> 12000 | G23: =IF(G$5<=假设!$D$25,假设!$D$18,0) -> 12000 | H23: =IF(H$5<=假设!$D$25,假设!$D$18,0) -> 0 | I23: =IF(I$5<=假设!$D$25,假设!$D$18,0) -> 0 | J23: =IF(J$5<=假设!$D$25,假设!$D$18,0) -> 0 | K23: =IF(K$5<=假设!$D$25,假设!$D$18,0) -> 0 | ... AM23: =IF(AM$5<=假设!$D$25,假设!$D$18,0) -> 0
C24: 经营结果（含品牌CAC） | D24: =D18-D20-D22-D23-D10 -> -12000 | E24: =E18-E20-E22-E23-E10 -> -12000 | F24: =F18-F20-F22-F23-F10 -> -12000 | G24: =G18-G20-G22-G23-G10 -> -12000 | H24: =H18-H20-H22-H23-H10 -> -11000 | I24: =I18-I20-I22-I23-I10 -> -11300 | J24: =J18-J20-J22-J23-J10 -> -8450 | K24: =K18-K20-K22-K23-K10 -> -5600 | ... AM24: =AM18-AM20-AM22-AM23-AM10 -> 54250
C25: 经营利润率 | D25: =IF(D14=0,"不适用",D24/D14) -> 不适用 | E25: =IF(E14=0,"不适用",E24/E14) -> 不适用 | F25: =IF(F14=0,"不适用",F24/F14) -> 不适用 | G25: =IF(G14=0,"不适用",G24/G14) -> 不适用 | H25: =IF(H14=0,"不适用",H24/H14) -> -0.91666667 | I25: =IF(I14=0,"不适用",I24/I14) -> -0.62777778 | J25: =IF(J14=0,"不适用",J24/J14) -> -0.35208333 | K25: =IF(K14=0,"不适用",K24/K14) -> -0.18666667 | ... AM25: =IF(AM14=0,"不适用",AM24/AM14) -> 0.36166667
C26: 开发现金支付 | D26: =IF(D$5<=假设!$D$25,(假设!$D$16+假设!$D$17)/假设!$D$25,0) -> 47437.5 | E26: =IF(E$5<=假设!$D$25,(假设!$D$16+假设!$D$17)/假设!$D$25,0) -> 47437.5 | F26: =IF(F$5<=假设!$D$25,(假设!$D$16+假设!$D$17)/假设!$D$25,0) -> 47437.5 | G26: =IF(G$5<=假设!$D$25,(假设!$D$16+假设!$D$17)/假设!$D$25,0) -> 47437.5 | H26: =IF(H$5<=假设!$D$25,(假设!$D$16+假设!$D$17)/假设!$D$25,0) -> 0 | I26: =IF(I$5<=假设!$D$25,(假设!$D$16+假设!$D$17)/假设!$D$25,0) -> 0 | J26: =IF(J$5<=假设!$D$25,(假设!$D$16+假设!$D$17)/假设!$D$25,0) -> 0 | K26: =IF(K$5<=假设!$D$25,(假设!$D$16+假设!$D$17)/假设!$D$25,0) -> 0 | ... AM26: =IF(AM$5<=假设!$D$25,(假设!$D$16+假设!$D$17)/假设!$D$25,0) -> 0
C27: 一次性启动现金支出 | D27: =IF(D$5=假设!$D$25+1,假设!$D$19,0) -> 0 | E27: =IF(E$5=假设!$D$25+1,假设!$D$19,0) -> 0 | F27: =IF(F$5=假设!$D$25+1,假设!$D$19,0) -> 0 | G27: =IF(G$5=假设!$D$25+1,假设!$D$19,0) -> 0 | H27: =IF(H$5=假设!$D$25+1,假设!$D$19,0) -> 50000 | I27: =IF(I$5=假设!$D$25+1,假设!$D$19,0) -> 0 | J27: =IF(J$5=假设!$D$25+1,假设!$D$19,0) -> 0 | K27: =IF(K$5=假设!$D$25+1,假设!$D$19,0) -> 0 | ... AM27: =IF(AM$5=假设!$D$25+1,假设!$D$19,0) -> 0
C28: 融资前税前现金流 | D28: =D24-D26-D27-D14+D33 -> -59437.5 | E28: =E24-E26-E27-E14+E33 -> -59437.5 | F28: =F24-F26-F27-F14+F33 -> -59437.5 | G28: =G24-G26-G27-G14+G33 -> -59437.5 | H28: =H24-H26-H27-H14+H33 -> -61000 | I28: =I24-I26-I27-I14+I33 -> -11300 | J28: =J24-J26-J27-J14+J33 -> -8450 | K28: =K24-K26-K27-K14+K33 -> -5600 | ... AM28: =AM24-AM26-AM27-AM14+AM33 -> 54250
C29: 累计公司现金流 | D29: =D28 -> -59437.5 | E29: =D29+E28 -> -118875 | F29: =E29+F28 -> -178312.5 | G29: =F29+G28 -> -237750 | H29: =G29+H28 -> -298750 | I29: =H29+I28 -> -310050 | J29: =I29+J28 -> -318500 | K29: =J29+K28 -> -324100 | L29: =K29+L28 -> -326850 | ... AM29: =AL29+AM28 -> 596400
C30: 含期初现金的余额 | D30: =假设!$D$23+D29 -> -59437.5 | E30: =假设!$D$23+E29 -> -118875 | F30: =假设!$D$23+F29 -> -178312.5 | G30: =假设!$D$23+G29 -> -237750 | H30: =假设!$D$23+H29 -> -298750 | I30: =假设!$D$23+I29 -> -310050 | J30: =假设!$D$23+J29 -> -318500 | K30: =假设!$D$23+K29 -> -324100 | ... AM30: =假设!$D$23+AM29 -> 596400
C31: 累计回本月标记 | D31: =IF(AND(D$5>假设!$D$25,D29>=0),D$5,999) -> 999 | E31: =IF(AND(E$5>假设!$D$25,E29>=0),E$5,999) -> 999 | F31: =IF(AND(F$5>假设!$D$25,F29>=0),F$5,999) -> 999 | G31: =IF(AND(G$5>假设!$D$25,G29>=0),G$5,999) -> 999 | H31: =IF(AND(H$5>假设!$D$25,H29>=0),H$5,999) -> 999 | I31: =IF(AND(I$5>假设!$D$25,I29>=0),I$5,999) -> 999 | J31: =IF(AND(J$5>假设!$D$25,J29>=0),J$5,999) -> 999 | K31: =IF(AND(K$5>假设!$D$25,K29>=0),K$5,999) -> 999 | ... AM31: =IF(AND(AM$5>假设!$D$25,AM29>=0),AM$5,999) -> 36
C32: 单月经营不亏标记 | D32: =IF(AND(D$5>假设!$D$25,D24>=0),D$5,999) -> 999 | E32: =IF(AND(E$5>假设!$D$25,E24>=0),E$5,999) -> 999 | F32: =IF(AND(F$5>假设!$D$25,F24>=0),F$5,999) -> 999 | G32: =IF(AND(G$5>假设!$D$25,G24>=0),G$5,999) -> 999 | H32: =IF(AND(H$5>假设!$D$25,H24>=0),H$5,999) -> 999 | I32: =IF(AND(I$5>假设!$D$25,I24>=0),I$5,999) -> 999 | J32: =IF(AND(J$5>假设!$D$25,J24>=0),J$5,999) -> 999 | K32: =IF(AND(K$5>假设!$D$25,K24>=0),K$5,999) -> 999 | ... AM32: =IF(AND(AM$5>假设!$D$25,AM24>=0),AM$5,999) -> 36
C33: 当月服务费现金收款 | D33: =IF(假设!$D$52=0,D14,0) -> 0 | E33: =IF(假设!$D$52=0,E14,D14) -> 0 | F33: =IF(假设!$D$52=0,F14,E14) -> 0 | G33: =IF(假设!$D$52=0,G14,F14) -> 0 | H33: =IF(假设!$D$52=0,H14,G14) -> 12000 | I33: =IF(假设!$D$52=0,I14,H14) -> 18000 | J33: =IF(假设!$D$52=0,J14,I14) -> 24000 | K33: =IF(假设!$D$52=0,K14,J14) -> 30000 | L33: =IF(假设!$D$52=0,L14,K14) -> 36000 | ... AM33: =IF(假设!$D$52=0,AM14,AL14) -> 150000
C34: 期末服务费应收款 | D34: =D14-D33 -> 0 | E34: =D34+E14-E33 -> 0 | F34: =E34+F14-F33 -> 0 | G34: =F34+G14-G33 -> 0 | H34: =G34+H14-H33 -> 0 | I34: =H34+I14-I33 -> 0 | J34: =I34+J14-J33 -> 0 | K34: =J34+K14-K33 -> 0 | L34: =K34+L14-L33 -> 0 | ... AM34: =AL34+AM14-AM33 -> 0
C35: M5首批获客已计入启动池；M6起新增/替补品牌另付CAC。当月获得品牌当月即完成全部活动。
C36: 现金流已含0/1月服务费收款延迟；未计税、利息及其余营运资金；不作税后净利。
C37: 固定费用不随规模增长仅为情景假设；扩张需另验容量、招聘、数据吞吐及报价。
C39: 支付费敏感性：全品牌资金费率 | D39: =假设!$D$50 -> 0.03 | E39: =假设!$D$50 -> 0.03 | F39: =假设!$D$50 -> 0.03 | G39: =假设!$D$50 -> 0.03 | H39: =假设!$D$50 -> 0.03 | I39: =假设!$D$50 -> 0.03 | J39: =假设!$D$50 -> 0.03 | K39: =假设!$D$50 -> 0.03 | ... AM39: =假设!$D$50 -> 0.03
C40: 敏感性现金流（同收款账期） | D40: =D28-(单位经济!$D$7*D39+假设!$D$51-假设!$D$11)*D6 -> -59437.5 | E40: =E28-(单位经济!$D$7*E39+假设!$D$51-假设!$D$11)*E6 -> -59437.5 | F40: =F28-(单位经济!$D$7*F39+假设!$D$51-假设!$D$11)*F6 -> -59437.5 | G40: =G28-(单位经济!$D$7*G39+假设!$D$51-假设!$D$11)*G6 -> -59437.5 | H40: =H28-(单位经济!$D$7*H39+假设!$D$51-假设!$D$11)*H6 -> -62560 | I40: =I28-(单位经济!$D$7*I39+假设!$D$51-假设!$D$11)*I6 -> -13640 | J40: =J28-(单位经济!$D$7*J39+假设!$D$51-假设!$D$11)*J6 -> -11570 | K40: =K28-(单位经济!$D$7*K39+假设!$D$51-假设!$D$11)*K6 -> -9500 | ... AM40: =AM28-(单位经济!$D$7*AM39+假设!$D$51-假设!$D$11)*AM6 -> 34750
C41: 敏感性累计现金流 | D41: =D40 -> -59437.5 | E41: =D41+E40 -> -118875 | F41: =E41+F40 -> -178312.5 | G41: =F41+G40 -> -237750 | H41: =G41+H40 -> -300310 | I41: =H41+I40 -> -313950 | J41: =I41+J40 -> -325520 | K41: =J41+K40 -> -335020 | L41: =K41+L40 -> -342450 | ... AM41: =AL41+AM40 -> 187680
C42: 敏感性回本月标记 | D42: =IF(AND(D$5>假设!$D$25,D41>=0),D$5,999) -> 999 | E42: =IF(AND(E$5>假设!$D$25,E41>=0),E$5,999) -> 999 | F42: =IF(AND(F$5>假设!$D$25,F41>=0),F$5,999) -> 999 | G42: =IF(AND(G$5>假设!$D$25,G41>=0),G$5,999) -> 999 | H42: =IF(AND(H$5>假设!$D$25,H41>=0),H$5,999) -> 999 | I42: =IF(AND(I$5>假设!$D$25,I41>=0),I$5,999) -> 999 | J42: =IF(AND(J$5>假设!$D$25,J41>=0),J$5,999) -> 999 | K42: =IF(AND(K$5>假设!$D$25,K41>=0),K$5,999) -> 999 | ... AM42: =IF(AND(AM$5>假设!$D$25,AM41>=0),AM$5,999) -> 36

Sheet 扩张现金流
C2: Wringy｜扩张现金流
C3: 扩张｜全部为说明情景；RM，M1–M36
D5: 1 | E5: 2 | F5: 3 | G5: 4 | H5: 5 | I5: 6 | J5: 7 | K5: 8 | L5: 9 | M5: 10 | N5: 11 | O5: 12 | P5: 13 | Q5: 14 | R5: 15 | S5: 16 | T5: 17 | U5: 18 | V5: 19 | W5: 20 | X5: 21 | Y5: 22 | Z5: 23 | AA5: 24 | AB5: 25 | AC5: 26 | AD5: 27 | AE5: 28 | AF5: 29 | AG5: 30 | AH5: 31 | AI5: 32 | AJ5: 33 | AK5: 34 | AL5: 35 | AM5: 36
C6: 活动数 | D6: =假设!D33 -> 0 | E6: =假设!E33 -> 0 | F6: =假设!F33 -> 0 | G6: =假设!G33 -> 0 | H6: =假设!H33 -> 12 | I6: =假设!I33 -> 20 | J6: =假设!J33 -> 28 | K6: =假设!K33 -> 36 | ... AM6: =假设!AM33 -> 240
C7: 活跃付费品牌（近似） | D7: =D6/假设!$D$21 -> 0 | E7: =E6/假设!$D$21 -> 0 | F7: =F6/假设!$D$21 -> 0 | G7: =G6/假设!$D$21 -> 0 | H7: =H6/假设!$D$21 -> 6 | I7: =I6/假设!$D$21 -> 10 | J7: =J6/假设!$D$21 -> 14 | K7: =K6/假设!$D$21 -> 18 | ... AM7: =AM6/假设!$D$21 -> 120
C8: 留存品牌 | D8: =0 -> 0 | E8: =MIN(E7,D7*(1-假设!$D$22)) -> 0 | F8: =MIN(F7,E7*(1-假设!$D$22)) -> 0 | G8: =MIN(G7,F7*(1-假设!$D$22)) -> 0 | H8: =MIN(H7,G7*(1-假设!$D$22)) -> 0 | I8: =MIN(I7,H7*(1-假设!$D$22)) -> 5.7 | J8: =MIN(J7,I7*(1-假设!$D$22)) -> 9.5 | K8: =MIN(K7,J7*(1-假设!$D$22)) -> 13.3 | L8: =MIN(L7,K7*(1-假设!$D$22)) -> 17.1 | ... AM8: =MIN(AM7,AL7*(1-假设!$D$22)) -> 114
C9: 新增／替补品牌 | D9: =MAX(0,D7-D8) -> 0 | E9: =MAX(0,E7-E8) -> 0 | F9: =MAX(0,F7-F8) -> 0 | G9: =MAX(0,G7-G8) -> 0 | H9: =MAX(0,H7-H8) -> 6 | I9: =MAX(0,I7-I8) -> 4.3 | J9: =MAX(0,J7-J8) -> 4.5 | K9: =MAX(0,K7-K8) -> 4.7 | ... AM9: =MAX(0,AM7-AM8) -> 6
C10: 独立品牌CAC现金支出 | D10: =IF(D$5<=假设!$D$25+1,0,D9*假设!$D$20) -> 0 | E10: =IF(E$5<=假设!$D$25+1,0,E9*假设!$D$20) -> 0 | F10: =IF(F$5<=假设!$D$25+1,0,F9*假设!$D$20) -> 0 | G10: =IF(G$5<=假设!$D$25+1,0,G9*假设!$D$20) -> 0 | H10: =IF(H$5<=假设!$D$25+1,0,H9*假设!$D$20) -> 0 | I10: =IF(I$5<=假设!$D$25+1,0,I9*假设!$D$20) -> 6450 | J10: =IF(J$5<=假设!$D$25+1,0,J9*假设!$D$20) -> 6750 | K10: =IF(K$5<=假设!$D$25+1,0,K9*假设!$D$20) -> 7050 | ... AM10: =IF(AM$5<=假设!$D$25+1,0,AM9*假设!$D$20) -> 9000
C11: 合格播放需求 | D11: =D6*单位经济!$D$10 -> 0 | E11: =E6*单位经济!$D$10 -> 0 | F11: =F6*单位经济!$D$10 -> 0 | G11: =G6*单位经济!$D$10 -> 0 | H11: =H6*单位经济!$D$10 -> 24000000 | I11: =I6*单位经济!$D$10 -> 40000000 | J11: =J6*单位经济!$D$10 -> 56000000 | K11: =K6*单位经济!$D$10 -> 72000000 | ... AM11: =AM6*单位经济!$D$10 -> 480000000
C12: 创作者奖励代转（非收入） | D12: =D6*假设!$D$6 -> 0 | E12: =E6*假设!$D$6 -> 0 | F12: =F6*假设!$D$6 -> 0 | G12: =G6*假设!$D$6 -> 0 | H12: =H6*假设!$D$6 -> 120000 | I12: =I6*假设!$D$6 -> 200000 | J12: =J6*假设!$D$6 -> 280000 | K12: =K6*假设!$D$6 -> 360000 | ... AM12: =AM6*假设!$D$6 -> 2400000
C13: 品牌总支出（未税） | D13: =D12+D14 -> 0 | E13: =E12+E14 -> 0 | F13: =F12+F14 -> 0 | G13: =G12+G14 -> 0 | H13: =H12+H14 -> 138000 | I13: =I12+I14 -> 230000 | J13: =J12+J14 -> 322000 | K13: =K12+K14 -> 414000 | ... AM13: =AM12+AM14 -> 2760000
C14: 平台服务收入 | D14: =D6*单位经济!$D$6 -> 0 | E14: =E6*单位经济!$D$6 -> 0 | F14: =F6*单位经济!$D$6 -> 0 | G14: =G6*单位经济!$D$6 -> 0 | H14: =H6*单位经济!$D$6 -> 18000 | I14: =I6*单位经济!$D$6 -> 30000 | J14: =J6*单位经济!$D$6 -> 42000 | K14: =K6*单位经济!$D$6 -> 54000 | ... AM14: =AM6*单位经济!$D$6 -> 360000
C15: 可变履约成本 | D15: =D6*单位经济!$D$11 -> 0 | E15: =E6*单位经济!$D$11 -> 0 | F15: =F6*单位经济!$D$11 -> 0 | G15: =G6*单位经济!$D$11 -> 0 | H15: =H6*单位经济!$D$11 -> 7200 | I15: =I6*单位经济!$D$11 -> 12000 | J15: =J6*单位经济!$D$11 -> 16800 | K15: =K6*单位经济!$D$11 -> 21600 | ... AM15: =AM6*单位经济!$D$11 -> 144000
C16: 固定履约成本 | D16: =IF(D$5>假设!$D$25,假设!$D$14,0) -> 0 | E16: =IF(E$5>假设!$D$25,假设!$D$14,0) -> 0 | F16: =IF(F$5>假设!$D$25,假设!$D$14,0) -> 0 | G16: =IF(G$5>假设!$D$25,假设!$D$14,0) -> 0 | H16: =IF(H$5>假设!$D$25,假设!$D$14,0) -> 2000 | I16: =IF(I$5>假设!$D$25,假设!$D$14,0) -> 2000 | J16: =IF(J$5>假设!$D$25,假设!$D$14,0) -> 2000 | K16: =IF(K$5>假设!$D$25,假设!$D$14,0) -> 2000 | ... AM16: =IF(AM$5>假设!$D$25,假设!$D$14,0) -> 2000
C17: 销售成本合计 | D17: =SUM(D15:D16) -> 0 | E17: =SUM(E15:E16) -> 0 | F17: =SUM(F15:F16) -> 0 | G17: =SUM(G15:G16) -> 0 | H17: =SUM(H15:H16) -> 9200 | I17: =SUM(I15:I16) -> 14000 | J17: =SUM(J15:J16) -> 18800 | K17: =SUM(K15:K16) -> 23600 | ... AM17: =SUM(AM15:AM16) -> 146000
C18: 毛利 | D18: =D14-D17 -> 0 | E18: =E14-E17 -> 0 | F18: =F14-F17 -> 0 | G18: =G14-G17 -> 0 | H18: =H14-H17 -> 8800 | I18: =I14-I17 -> 16000 | J18: =J14-J17 -> 23200 | K18: =K14-K17 -> 30400 | ... AM18: =AM14-AM17 -> 214000
C19: 毛利率 | D19: =IF(D14=0,"不适用",D18/D14) -> 不适用 | E19: =IF(E14=0,"不适用",E18/E14) -> 不适用 | F19: =IF(F14=0,"不适用",F18/F14) -> 不适用 | G19: =IF(G14=0,"不适用",G18/G14) -> 不适用 | H19: =IF(H14=0,"不适用",H18/H14) -> 0.48888889 | I19: =IF(I14=0,"不适用",I18/I14) -> 0.53333333 | J19: =IF(J14=0,"不适用",J18/J14) -> 0.55238095 | K19: =IF(K14=0,"不适用",K18/K14) -> 0.56296296 | ... AM19: =IF(AM14=0,"不适用",AM18/AM14) -> 0.59444444
C20: 活动获取佣金 | D20: =D6*假设!$D$13 -> 0 | E20: =E6*假设!$D$13 -> 0 | F20: =F6*假设!$D$13 -> 0 | G20: =G6*假设!$D$13 -> 0 | H20: =H6*假设!$D$13 -> 1800 | I20: =I6*假设!$D$13 -> 3000 | J20: =J6*假设!$D$13 -> 4200 | K20: =K6*假设!$D$13 -> 5400 | ... AM20: =AM6*假设!$D$13 -> 36000
C21: 贡献（CAC前） | D21: =D14-D15-D20 -> 0 | E21: =E14-E15-E20 -> 0 | F21: =F14-F15-F20 -> 0 | G21: =G14-G15-G20 -> 0 | H21: =H14-H15-H20 -> 9000 | I21: =I14-I15-I20 -> 15000 | J21: =J14-J15-J20 -> 21000 | K21: =K14-K15-K20 -> 27000 | ... AM21: =AM14-AM15-AM20 -> 180000
C22: 固定非履约支出 | D22: =IF(D$5>假设!$D$25,假设!$D$15,0) -> 0 | E22: =IF(E$5>假设!$D$25,假设!$D$15,0) -> 0 | F22: =IF(F$5>假设!$D$25,假设!$D$15,0) -> 0 | G22: =IF(G$5>假设!$D$25,假设!$D$15,0) -> 0 | H22: =IF(H$5>假设!$D$25,假设!$D$15,0) -> 15000 | I22: =IF(I$5>假设!$D$25,假设!$D$15,0) -> 15000 | J22: =IF(J$5>假设!$D$25,假设!$D$15,0) -> 15000 | K22: =IF(K$5>假设!$D$25,假设!$D$15,0) -> 15000 | ... AM22: =IF(AM$5>假设!$D$25,假设!$D$15,0) -> 15000
C23: 建设期运营支出 | D23: =IF(D$5<=假设!$D$25,假设!$D$18,0) -> 12000 | E23: =IF(E$5<=假设!$D$25,假设!$D$18,0) -> 12000 | F23: =IF(F$5<=假设!$D$25,假设!$D$18,0) -> 12000 | G23: =IF(G$5<=假设!$D$25,假设!$D$18,0) -> 12000 | H23: =IF(H$5<=假设!$D$25,假设!$D$18,0) -> 0 | I23: =IF(I$5<=假设!$D$25,假设!$D$18,0) -> 0 | J23: =IF(J$5<=假设!$D$25,假设!$D$18,0) -> 0 | K23: =IF(K$5<=假设!$D$25,假设!$D$18,0) -> 0 | ... AM23: =IF(AM$5<=假设!$D$25,假设!$D$18,0) -> 0
C24: 经营结果（含品牌CAC） | D24: =D18-D20-D22-D23-D10 -> -12000 | E24: =E18-E20-E22-E23-E10 -> -12000 | F24: =F18-F20-F22-F23-F10 -> -12000 | G24: =G18-G20-G22-G23-G10 -> -12000 | H24: =H18-H20-H22-H23-H10 -> -8000 | I24: =I18-I20-I22-I23-I10 -> -8450 | J24: =J18-J20-J22-J23-J10 -> -2750 | K24: =K18-K20-K22-K23-K10 -> 2950 | ... AM24: =AM18-AM20-AM22-AM23-AM10 -> 154000
C25: 经营利润率 | D25: =IF(D14=0,"不适用",D24/D14) -> 不适用 | E25: =IF(E14=0,"不适用",E24/E14) -> 不适用 | F25: =IF(F14=0,"不适用",F24/F14) -> 不适用 | G25: =IF(G14=0,"不适用",G24/G14) -> 不适用 | H25: =IF(H14=0,"不适用",H24/H14) -> -0.44444444 | I25: =IF(I14=0,"不适用",I24/I14) -> -0.28166667 | J25: =IF(J14=0,"不适用",J24/J14) -> -0.06547619 | K25: =IF(K14=0,"不适用",K24/K14) -> 0.05462963 | ... AM25: =IF(AM14=0,"不适用",AM24/AM14) -> 0.42777778
C26: 开发现金支付 | D26: =IF(D$5<=假设!$D$25,(假设!$D$16+假设!$D$17)/假设!$D$25,0) -> 47437.5 | E26: =IF(E$5<=假设!$D$25,(假设!$D$16+假设!$D$17)/假设!$D$25,0) -> 47437.5 | F26: =IF(F$5<=假设!$D$25,(假设!$D$16+假设!$D$17)/假设!$D$25,0) -> 47437.5 | G26: =IF(G$5<=假设!$D$25,(假设!$D$16+假设!$D$17)/假设!$D$25,0) -> 47437.5 | H26: =IF(H$5<=假设!$D$25,(假设!$D$16+假设!$D$17)/假设!$D$25,0) -> 0 | I26: =IF(I$5<=假设!$D$25,(假设!$D$16+假设!$D$17)/假设!$D$25,0) -> 0 | J26: =IF(J$5<=假设!$D$25,(假设!$D$16+假设!$D$17)/假设!$D$25,0) -> 0 | K26: =IF(K$5<=假设!$D$25,(假设!$D$16+假设!$D$17)/假设!$D$25,0) -> 0 | ... AM26: =IF(AM$5<=假设!$D$25,(假设!$D$16+假设!$D$17)/假设!$D$25,0) -> 0
C27: 一次性启动现金支出 | D27: =IF(D$5=假设!$D$25+1,假设!$D$19,0) -> 0 | E27: =IF(E$5=假设!$D$25+1,假设!$D$19,0) -> 0 | F27: =IF(F$5=假设!$D$25+1,假设!$D$19,0) -> 0 | G27: =IF(G$5=假设!$D$25+1,假设!$D$19,0) -> 0 | H27: =IF(H$5=假设!$D$25+1,假设!$D$19,0) -> 50000 | I27: =IF(I$5=假设!$D$25+1,假设!$D$19,0) -> 0 | J27: =IF(J$5=假设!$D$25+1,假设!$D$19,0) -> 0 | K27: =IF(K$5=假设!$D$25+1,假设!$D$19,0) -> 0 | ... AM27: =IF(AM$5=假设!$D$25+1,假设!$D$19,0) -> 0
C28: 融资前税前现金流 | D28: =D24-D26-D27-D14+D33 -> -59437.5 | E28: =E24-E26-E27-E14+E33 -> -59437.5 | F28: =F24-F26-F27-F14+F33 -> -59437.5 | G28: =G24-G26-G27-G14+G33 -> -59437.5 | H28: =H24-H26-H27-H14+H33 -> -58000 | I28: =I24-I26-I27-I14+I33 -> -8450 | J28: =J24-J26-J27-J14+J33 -> -2750 | K28: =K24-K26-K27-K14+K33 -> 2950 | ... AM28: =AM24-AM26-AM27-AM14+AM33 -> 154000
C29: 累计公司现金流 | D29: =D28 -> -59437.5 | E29: =D29+E28 -> -118875 | F29: =E29+F28 -> -178312.5 | G29: =F29+G28 -> -237750 | H29: =G29+H28 -> -295750 | I29: =H29+I28 -> -304200 | J29: =I29+J28 -> -306950 | K29: =J29+K28 -> -304000 | L29: =K29+L28 -> -295350 | ... AM29: =AL29+AM28 -> 2256675
C30: 含期初现金的余额 | D30: =假设!$D$23+D29 -> -59437.5 | E30: =假设!$D$23+E29 -> -118875 | F30: =假设!$D$23+F29 -> -178312.5 | G30: =假设!$D$23+G29 -> -237750 | H30: =假设!$D$23+H29 -> -295750 | I30: =假设!$D$23+I29 -> -304200 | J30: =假设!$D$23+J29 -> -306950 | K30: =假设!$D$23+K29 -> -304000 | ... AM30: =假设!$D$23+AM29 -> 2256675
C31: 累计回本月标记 | D31: =IF(AND(D$5>假设!$D$25,D29>=0),D$5,999) -> 999 | E31: =IF(AND(E$5>假设!$D$25,E29>=0),E$5,999) -> 999 | F31: =IF(AND(F$5>假设!$D$25,F29>=0),F$5,999) -> 999 | G31: =IF(AND(G$5>假设!$D$25,G29>=0),G$5,999) -> 999 | H31: =IF(AND(H$5>假设!$D$25,H29>=0),H$5,999) -> 999 | I31: =IF(AND(I$5>假设!$D$25,I29>=0),I$5,999) -> 999 | J31: =IF(AND(J$5>假设!$D$25,J29>=0),J$5,999) -> 999 | K31: =IF(AND(K$5>假设!$D$25,K29>=0),K$5,999) -> 999 | ... AM31: =IF(AND(AM$5>假设!$D$25,AM29>=0),AM$5,999) -> 36
C32: 单月经营不亏标记 | D32: =IF(AND(D$5>假设!$D$25,D24>=0),D$5,999) -> 999 | E32: =IF(AND(E$5>假设!$D$25,E24>=0),E$5,999) -> 999 | F32: =IF(AND(F$5>假设!$D$25,F24>=0),F$5,999) -> 999 | G32: =IF(AND(G$5>假设!$D$25,G24>=0),G$5,999) -> 999 | H32: =IF(AND(H$5>假设!$D$25,H24>=0),H$5,999) -> 999 | I32: =IF(AND(I$5>假设!$D$25,I24>=0),I$5,999) -> 999 | J32: =IF(AND(J$5>假设!$D$25,J24>=0),J$5,999) -> 999 | K32: =IF(AND(K$5>假设!$D$25,K24>=0),K$5,999) -> 8 | ... AM32: =IF(AND(AM$5>假设!$D$25,AM24>=0),AM$5,999) -> 36
C33: 当月服务费现金收款 | D33: =IF(假设!$D$52=0,D14,0) -> 0 | E33: =IF(假设!$D$52=0,E14,D14) -> 0 | F33: =IF(假设!$D$52=0,F14,E14) -> 0 | G33: =IF(假设!$D$52=0,G14,F14) -> 0 | H33: =IF(假设!$D$52=0,H14,G14) -> 18000 | I33: =IF(假设!$D$52=0,I14,H14) -> 30000 | J33: =IF(假设!$D$52=0,J14,I14) -> 42000 | K33: =IF(假设!$D$52=0,K14,J14) -> 54000 | L33: =IF(假设!$D$52=0,L14,K14) -> 66000 | ... AM33: =IF(假设!$D$52=0,AM14,AL14) -> 360000
C34: 期末服务费应收款 | D34: =D14-D33 -> 0 | E34: =D34+E14-E33 -> 0 | F34: =E34+F14-F33 -> 0 | G34: =F34+G14-G33 -> 0 | H34: =G34+H14-H33 -> 0 | I34: =H34+I14-I33 -> 0 | J34: =I34+J14-J33 -> 0 | K34: =J34+K14-K33 -> 0 | L34: =K34+L14-L33 -> 0 | ... AM34: =AL34+AM14-AM33 -> 0
C35: M5首批获客已计入启动池；M6起新增/替补品牌另付CAC。当月获得品牌当月即完成全部活动。
C36: 现金流已含0/1月服务费收款延迟；未计税、利息及其余营运资金；不作税后净利。
C37: 固定费用不随规模增长仅为情景假设；扩张需另验容量、招聘、数据吞吐及报价。
C39: 支付费敏感性：全品牌资金费率 | D39: =假设!$D$50 -> 0.03 | E39: =假设!$D$50 -> 0.03 | F39: =假设!$D$50 -> 0.03 | G39: =假设!$D$50 -> 0.03 | H39: =假设!$D$50 -> 0.03 | I39: =假设!$D$50 -> 0.03 | J39: =假设!$D$50 -> 0.03 | K39: =假设!$D$50 -> 0.03 | ... AM39: =假设!$D$50 -> 0.03
C40: 敏感性现金流（同收款账期） | D40: =D28-(单位经济!$D$7*D39+假设!$D$51-假设!$D$11)*D6 -> -59437.5 | E40: =E28-(单位经济!$D$7*E39+假设!$D$51-假设!$D$11)*E6 -> -59437.5 | F40: =F28-(单位经济!$D$7*F39+假设!$D$51-假设!$D$11)*F6 -> -59437.5 | G40: =G28-(单位经济!$D$7*G39+假设!$D$51-假设!$D$11)*G6 -> -59437.5 | H40: =H28-(单位经济!$D$7*H39+假设!$D$51-假设!$D$11)*H6 -> -60340 | I40: =I28-(单位经济!$D$7*I39+假设!$D$51-假设!$D$11)*I6 -> -12350 | J40: =J28-(单位经济!$D$7*J39+假设!$D$51-假设!$D$11)*J6 -> -8210 | K40: =K28-(单位经济!$D$7*K39+假设!$D$51-假设!$D$11)*K6 -> -4070 | ... AM40: =AM28-(单位经济!$D$7*AM39+假设!$D$51-假设!$D$11)*AM6 -> 107200
C41: 敏感性累计现金流 | D41: =D40 -> -59437.5 | E41: =D41+E40 -> -118875 | F41: =E41+F40 -> -178312.5 | G41: =F41+G40 -> -237750 | H41: =G41+H40 -> -298090 | I41: =H41+I40 -> -310440 | J41: =I41+J40 -> -318650 | K41: =J41+K40 -> -322720 | L41: =K41+L40 -> -322650 | ... AM41: =AL41+AM40 -> 1367085
C42: 敏感性回本月标记 | D42: =IF(AND(D$5>假设!$D$25,D41>=0),D$5,999) -> 999 | E42: =IF(AND(E$5>假设!$D$25,E41>=0),E$5,999) -> 999 | F42: =IF(AND(F$5>假设!$D$25,F41>=0),F$5,999) -> 999 | G42: =IF(AND(G$5>假设!$D$25,G41>=0),G$5,999) -> 999 | H42: =IF(AND(H$5>假设!$D$25,H41>=0),H$5,999) -> 999 | I42: =IF(AND(I$5>假设!$D$25,I41>=0),I$5,999) -> 999 | J42: =IF(AND(J$5>假设!$D$25,J41>=0),J$5,999) -> 999 | K42: =IF(AND(K$5>假设!$D$25,K41>=0),K$5,999) -> 999 | ... AM42: =IF(AND(AM$5>假设!$D$25,AM41>=0),AM$5,999) -> 36

Sheet 品牌获客回收
C2: Wringy｜品牌获客回收
C5: 独立品牌获客经济 | D5: 数值
C6: 独立品牌CAC | D6: =假设!$D$20 -> 1500
C7: 每月活动／品牌 | D7: =假设!$D$21 -> 2
C8: 每场贡献（已扣150佣金） | D8: =单位经济!D13 -> 750
C9: 每品牌月贡献 | D9: =D7*D8 -> 1500
C10: 简单回收期（月；持续采购） | D10: =IF(D9<=0,"无法回收",D6/D9) -> 1
C12: 单品牌持续每月2场、不流失的简单回收期；非观察到的客户群回收期。
C13: 下表为1个新品牌的留存期望贡献；第1月完整贡献，第2月起按留存衰减。
C15: 品牌年龄（月） | D15: 预期留存品牌 | E15: 月贡献 | F15: 累计贡献 | G15: 扣CAC后累计
C16: 1 | D16: =(1-假设!$D$22)^(C16-1) -> 1 | E16: =D16*$D$9 -> 1500 | F16: =E16 -> 1500 | G16: =F16-$D$6 -> 0
C17: 2 | D17: =(1-假设!$D$22)^(C17-1) -> 0.95 | E17: =D17*$D$9 -> 1425 | F17: =F16+E17 -> 2925 | G17: =F17-$D$6 -> 1425
C18: 3 | D18: =(1-假设!$D$22)^(C18-1) -> 0.9025 | E18: =D18*$D$9 -> 1353.75 | F18: =F17+E18 -> 4278.75 | G18: =F18-$D$6 -> 2778.75
C19: 4 | D19: =(1-假设!$D$22)^(C19-1) -> 0.857375 | E19: =D19*$D$9 -> 1286.0625 | F19: =F18+E19 -> 5564.8125 | G19: =F19-$D$6 -> 4064.8125
C20: 5 | D20: =(1-假设!$D$22)^(C20-1) -> 0.81450625 | E20: =D20*$D$9 -> 1221.7594 | F20: =F19+E20 -> 6786.5719 | G20: =F20-$D$6 -> 5286.5719
C21: 6 | D21: =(1-假设!$D$22)^(C21-1) -> 0.77378094 | E21: =D21*$D$9 -> 1160.6714 | F21: =F20+E21 -> 7947.2433 | G21: =F21-$D$6 -> 6447.2433
C22: 7 | D22: =(1-假设!$D$22)^(C22-1) -> 0.73509189 | E22: =D22*$D$9 -> 1102.6378 | F22: =F21+E22 -> 9049.8811 | G22: =F22-$D$6 -> 7549.8811
C23: 8 | D23: =(1-假设!$D$22)^(C23-1) -> 0.6983373 | E23: =D23*$D$9 -> 1047.5059 | F23: =F22+E23 -> 10097.387 | G23: =F23-$D$6 -> 8597.3871
C24: 9 | D24: =(1-假设!$D$22)^(C24-1) -> 0.66342043 | E24: =D24*$D$9 -> 995.13065 | F24: =F23+E24 -> 11092.518 | G24: =F24-$D$6 -> 9592.5177
C25: 10 | D25: =(1-假设!$D$22)^(C25-1) -> 0.63024941 | E25: =D25*$D$9 -> 945.37411 | F25: =F24+E25 -> 12037.892 | G25: =F25-$D$6 -> 10537.892
C26: 11 | D26: =(1-假设!$D$22)^(C26-1) -> 0.59873694 | E26: =D26*$D$9 -> 898.10541 | F26: =F25+E26 -> 12935.997 | G26: =F26-$D$6 -> 11435.997
C27: 12 | D27: =(1-假设!$D$22)^(C27-1) -> 0.56880009 | E27: =D27*$D$9 -> 853.20014 | F27: =F26+E27 -> 13789.197 | G27: =F27-$D$6 -> 12289.197
C28: 13 | D28: =(1-假设!$D$22)^(C28-1) -> 0.54036009 | E28: =D28*$D$9 -> 810.54013 | F28: =F27+E28 -> 14599.738 | G28: =F28-$D$6 -> 13099.738
... C51: 36 | D51: =(1-假设!$D$22)^(C51-1) -> 0.16608338 | E51: =D51*$D$9 -> 249.12508 | F51: =F50+E51 -> 25266.624 | G51: =F51-$D$6 -> 23766.624
C54: 这是贡献口径回收，不分摊固定支出；无销售前置周期、退款或复购延迟假设。

Sheet 敏感性
C2: Wringy｜敏感性
C3: 公式即时计算｜每月经营结果：未含新增品牌CAC；其影响见下方独立敏感性。
C5: 活动数／服务费率 | D5: 0.1 | E5: 0.125 | F5: 0.15 | G5: 0.175 | H5: 0.2
C6: 10 | D6: =$C6*(假设!$D$6*D$5-单位经济!$D$11-假设!$D$13)-单位经济!$D$21 -> -14500 | E6: =$C6*(假设!$D$6*E$5-单位经济!$D$11-假设!$D$13)-单位经济!$D$21 -> -12000 | F6: =$C6*(假设!$D$6*F$5-单位经济!$D$11-假设!$D$13)-单位经济!$D$21 -> -9500 | G6: =$C6*(假设!$D$6*G$5-单位经济!$D$11-假设!$D$13)-单位经济!$D$21 -> -7000 | H6: =$C6*(假设!$D$6*H$5-单位经济!$D$11-假设!$D$13)-单位经济!$D$21 -> -4500
C7: 20 | D7: =$C7*(假设!$D$6*D$5-单位经济!$D$11-假设!$D$13)-单位经济!$D$21 -> -12000 | E7: =$C7*(假设!$D$6*E$5-单位经济!$D$11-假设!$D$13)-单位经济!$D$21 -> -7000 | F7: =$C7*(假设!$D$6*F$5-单位经济!$D$11-假设!$D$13)-单位经济!$D$21 -> -2000 | G7: =$C7*(假设!$D$6*G$5-单位经济!$D$11-假设!$D$13)-单位经济!$D$21 -> 3000 | H7: =$C7*(假设!$D$6*H$5-单位经济!$D$11-假设!$D$13)-单位经济!$D$21 -> 8000
C8: 23 | D8: =$C8*(假设!$D$6*D$5-单位经济!$D$11-假设!$D$13)-单位经济!$D$21 -> -11250 | E8: =$C8*(假设!$D$6*E$5-单位经济!$D$11-假设!$D$13)-单位经济!$D$21 -> -5500 | F8: =$C8*(假设!$D$6*F$5-单位经济!$D$11-假设!$D$13)-单位经济!$D$21 -> 250 | G8: =$C8*(假设!$D$6*G$5-单位经济!$D$11-假设!$D$13)-单位经济!$D$21 -> 6000 | H8: =$C8*(假设!$D$6*H$5-单位经济!$D$11-假设!$D$13)-单位经济!$D$21 -> 11750
C9: 40 | D9: =$C9*(假设!$D$6*D$5-单位经济!$D$11-假设!$D$13)-单位经济!$D$21 -> -7000 | E9: =$C9*(假设!$D$6*E$5-单位经济!$D$11-假设!$D$13)-单位经济!$D$21 -> 3000 | F9: =$C9*(假设!$D$6*F$5-单位经济!$D$11-假设!$D$13)-单位经济!$D$21 -> 13000 | G9: =$C9*(假设!$D$6*G$5-单位经济!$D$11-假设!$D$13)-单位经济!$D$21 -> 23000 | H9: =$C9*(假设!$D$6*H$5-单位经济!$D$11-假设!$D$13)-单位经济!$D$21 -> 33000
C10: 80 | D10: =$C10*(假设!$D$6*D$5-单位经济!$D$11-假设!$D$13)-单位经济!$D$21 -> 3000 | E10: =$C10*(假设!$D$6*E$5-单位经济!$D$11-假设!$D$13)-单位经济!$D$21 -> 23000 | F10: =$C10*(假设!$D$6*F$5-单位经济!$D$11-假设!$D$13)-单位经济!$D$21 -> 43000 | G10: =$C10*(假设!$D$6*G$5-单位经济!$D$11-假设!$D$13)-单位经济!$D$21 -> 63000 | H10: =$C10*(假设!$D$6*H$5-单位经济!$D$11-假设!$D$13)-单位经济!$D$21 -> 83000
C11: 160 | D11: =$C11*(假设!$D$6*D$5-单位经济!$D$11-假设!$D$13)-单位经济!$D$21 -> 23000 | E11: =$C11*(假设!$D$6*E$5-单位经济!$D$11-假设!$D$13)-单位经济!$D$21 -> 63000 | F11: =$C11*(假设!$D$6*F$5-单位经济!$D$11-假设!$D$13)-单位经济!$D$21 -> 103000 | G11: =$C11*(假设!$D$6*G$5-单位经济!$D$11-假设!$D$13)-单位经济!$D$21 -> 143000 | H11: =$C11*(假设!$D$6*H$5-单位经济!$D$11-假设!$D$13)-单位经济!$D$21 -> 183000
C15: 履约成本／费率 | D15: 0.1 | E15: 0.125 | F15: 0.15 | G15: 0.175 | H15: 0.2
C16: 400 | D16: =IF(假设!$D$6*D$15-$C16-假设!$D$13<=0,"无法达成",ROUNDUP(单位经济!$D$21/(假设!$D$6*D$15-$C16-假设!$D$13),0)) -> 38 | E16: =IF(假设!$D$6*E$15-$C16-假设!$D$13<=0,"无法达成",ROUNDUP(单位经济!$D$21/(假设!$D$6*E$15-$C16-假设!$D$13),0)) -> 25 | F16: =IF(假设!$D$6*F$15-$C16-假设!$D$13<=0,"无法达成",ROUNDUP(单位经济!$D$21/(假设!$D$6*F$15-$C16-假设!$D$13),0)) -> 18 | G16: =IF(假设!$D$6*G$15-$C16-假设!$D$13<=0,"无法达成",ROUNDUP(单位经济!$D$21/(假设!$D$6*G$15-$C16-假设!$D$13),0)) -> 15 | H16: =IF(假设!$D$6*H$15-$C16-假设!$D$13<=0,"无法达成",ROUNDUP(单位经济!$D$21/(假设!$D$6*H$15-$C16-假设!$D$13),0)) -> 12
C17: 600 | D17: =IF(假设!$D$6*D$15-$C17-假设!$D$13<=0,"无法达成",ROUNDUP(单位经济!$D$21/(假设!$D$6*D$15-$C17-假设!$D$13),0)) -> 68 | E17: =IF(假设!$D$6*E$15-$C17-假设!$D$13<=0,"无法达成",ROUNDUP(单位经济!$D$21/(假设!$D$6*E$15-$C17-假设!$D$13),0)) -> 34 | F17: =IF(假设!$D$6*F$15-$C17-假设!$D$13<=0,"无法达成",ROUNDUP(单位经济!$D$21/(假设!$D$6*F$15-$C17-假设!$D$13),0)) -> 23 | G17: =IF(假设!$D$6*G$15-$C17-假设!$D$13<=0,"无法达成",ROUNDUP(单位经济!$D$21/(假设!$D$6*G$15-$C17-假设!$D$13),0)) -> 17 | H17: =IF(假设!$D$6*H$15-$C17-假设!$D$13<=0,"无法达成",ROUNDUP(单位经济!$D$21/(假设!$D$6*H$15-$C17-假设!$D$13),0)) -> 14
C18: 800 | D18: =IF(假设!$D$6*D$15-$C18-假设!$D$13<=0,"无法达成",ROUNDUP(单位经济!$D$21/(假设!$D$6*D$15-$C18-假设!$D$13),0)) -> 340 | E18: =IF(假设!$D$6*E$15-$C18-假设!$D$13<=0,"无法达成",ROUNDUP(单位经济!$D$21/(假设!$D$6*E$15-$C18-假设!$D$13),0)) -> 57 | F18: =IF(假设!$D$6*F$15-$C18-假设!$D$13<=0,"无法达成",ROUNDUP(单位经济!$D$21/(假设!$D$6*F$15-$C18-假设!$D$13),0)) -> 31 | G18: =IF(假设!$D$6*G$15-$C18-假设!$D$13<=0,"无法达成",ROUNDUP(单位经济!$D$21/(假设!$D$6*G$15-$C18-假设!$D$13),0)) -> 22 | H18: =IF(假设!$D$6*H$15-$C18-假设!$D$13<=0,"无法达成",ROUNDUP(单位经济!$D$21/(假设!$D$6*H$15-$C18-假设!$D$13),0)) -> 17
C19: 1000 | D19: =IF(假设!$D$6*D$15-$C19-假设!$D$13<=0,"无法达成",ROUNDUP(单位经济!$D$21/(假设!$D$6*D$15-$C19-假设!$D$13),0)) -> 无法达成 | E19: =IF(假设!$D$6*E$15-$C19-假设!$D$13<=0,"无法达成",ROUNDUP(单位经济!$D$21/(假设!$D$6*E$15-$C19-假设!$D$13),0)) -> 170 | F19: =IF(假设!$D$6*F$15-$C19-假设!$D$13<=0,"无法达成",ROUNDUP(单位经济!$D$21/(假设!$D$6*F$15-$C19-假设!$D$13),0)) -> 49 | G19: =IF(假设!$D$6*G$15-$C19-假设!$D$13<=0,"无法达成",ROUNDUP(单位经济!$D$21/(假设!$D$6*G$15-$C19-假设!$D$13),0)) -> 29 | H19: =IF(假设!$D$6*H$15-$C19-假设!$D$13<=0,"无法达成",ROUNDUP(单位经济!$D$21/(假设!$D$6*H$15-$C19-假设!$D$13),0)) -> 20
C20: 1500 | D20: =IF(假设!$D$6*D$15-$C20-假设!$D$13<=0,"无法达成",ROUNDUP(单位经济!$D$21/(假设!$D$6*D$15-$C20-假设!$D$13),0)) -> 无法达成 | E20: =IF(假设!$D$6*E$15-$C20-假设!$D$13<=0,"无法达成",ROUNDUP(单位经济!$D$21/(假设!$D$6*E$15-$C20-假设!$D$13),0)) -> 无法达成 | F20: =IF(假设!$D$6*F$15-$C20-假设!$D$13<=0,"无法达成",ROUNDUP(单位经济!$D$21/(假设!$D$6*F$15-$C20-假设!$D$13),0)) -> 无法达成 | G20: =IF(假设!$D$6*G$15-$C20-假设!$D$13<=0,"无法达成",ROUNDUP(单位经济!$D$21/(假设!$D$6*G$15-$C20-假设!$D$13),0)) -> 170 | H20: =IF(假设!$D$6*H$15-$C20-假设!$D$13<=0,"无法达成",ROUNDUP(单位经济!$D$21/(假设!$D$6*H$15-$C20-假设!$D$13),0)) -> 49
C22: 上表：覆盖固定费用所需活动数（新增品牌CAC之前），向上取整。
C25: 新增品牌数／CAC | D25: 750 | E25: 1500 | F25: 2250 | G25: 3000
C26: 0 | D26: =单位经济!$D$22-$C26*D$25 -> -2000 | E26: =单位经济!$D$22-$C26*E$25 -> -2000 | F26: =单位经济!$D$22-$C26*F$25 -> -2000 | G26: =单位经济!$D$22-$C26*G$25 -> -2000
C27: 2 | D27: =单位经济!$D$22-$C27*D$25 -> -3500 | E27: =单位经济!$D$22-$C27*E$25 -> -5000 | F27: =单位经济!$D$22-$C27*F$25 -> -6500 | G27: =单位经济!$D$22-$C27*G$25 -> -8000
C28: 5 | D28: =单位经济!$D$22-$C28*D$25 -> -5750 | E28: =单位经济!$D$22-$C28*E$25 -> -9500 | F28: =单位经济!$D$22-$C28*F$25 -> -13250 | G28: =单位经济!$D$22-$C28*G$25 -> -17000
C29: 10 | D29: =单位经济!$D$22-$C29*D$25 -> -9500 | E29: =单位经济!$D$22-$C29*E$25 -> -17000 | F29: =单位经济!$D$22-$C29*F$25 -> -24500 | G29: =单位经济!$D$22-$C29*G$25 -> -32000
C30: 20 | D30: =单位经济!$D$22-$C30*D$25 -> -17000 | E30: =单位经济!$D$22-$C30*E$25 -> -32000 | F30: =单位经济!$D$22-$C30*F$25 -> -47000 | G30: =单位经济!$D$22-$C30*G$25 -> -62000
C32: 上表：按单位经济示例活动量，扣独立品牌CAC后的月经营结果。
C35: 全资金支付费率 | D35: 每场支付成本 | E35: 每场贡献 | F35: 20场毛利率 | G35: 20场经营（CAC前）
C36: 0 | D36: =单位经济!$D$7*C36+假设!$D$51 -> 0 | E36: =单位经济!$D$13+假设!$D$11-D36 -> 900 | F36: =(单位经济!$D$18+(假设!$D$11-D36)*假设!$D$24)/单位经济!$D$16 -> 0.63333333 | G36: =单位经济!$D$22+(假设!$D$11-D36)*假设!$D$24 -> 1000
C37: 0.02 | D37: =单位经济!$D$7*C37+假设!$D$51 -> 230 | E37: =单位经济!$D$13+假设!$D$11-D37 -> 670 | F37: =(单位经济!$D$18+(假设!$D$11-D37)*假设!$D$24)/单位经济!$D$16 -> 0.48 | G37: =单位经济!$D$22+(假设!$D$11-D37)*假设!$D$24 -> -3600
C38: 0.03 | D38: =单位经济!$D$7*C38+假设!$D$51 -> 345 | E38: =单位经济!$D$13+假设!$D$11-D38 -> 555 | F38: =(单位经济!$D$18+(假设!$D$11-D38)*假设!$D$24)/单位经济!$D$16 -> 0.40333333 | G38: =单位经济!$D$22+(假设!$D$11-D38)*假设!$D$24 -> -5900
C39: 0.04 | D39: =单位经济!$D$7*C39+假设!$D$51 -> 460 | E39: =单位经济!$D$13+假设!$D$11-D39 -> 440 | F39: =(单位经济!$D$18+(假设!$D$11-D39)*假设!$D$24)/单位经济!$D$16 -> 0.32666667 | G39: =单位经济!$D$22+(假设!$D$11-D39)*假设!$D$24 -> -8200
C41: 3%×RM11,500＝RM345；未加待报价出款固定费。改假设D49为1可重算所有公司回本。
C44: 全品牌资金费率情景 | D44: 保守 | E44: 基准 | F44: 扩张
C45: 公司累计回本（月序） | D45: =IF(MIN(保守现金流!D42:AM42)=999,"36个月内未回本",MIN(保守现金流!D42:AM42)) -> 36个月内未回本 | E45: =IF(MIN(基准现金流!D42:AM42)=999,"36个月内未回本",MIN(基准现金流!D42:AM42)) -> 31 | F45: =IF(MIN(扩张现金流!D42:AM42)=999,"36个月内未回本",MIN(扩张现金流!D42:AM42)) -> 21
C46: 峰值资金缺口／RM | D46: =MAX(0,-MIN(保守现金流!D41:AM41)) -> 469245 | E46: =MAX(0,-MIN(基准现金流!D41:AM41)) -> 352320 | F46: =MAX(0,-MIN(扩张现金流!D41:AM41)) -> 322720
C47: 36个月累计现金流／RM | D47: =保守现金流!AM41 -> -469245 | E47: =基准现金流!AM41 -> 187680 | F47: =扩张现金流!AM41 -> 1367085
C49: 此表使用假设中的全资金费率（默认3%），同其他成本及收款账期实时计算。
